Workbook

Sheet ÖZET
AA1: W.CASHEW NUT W320 KAV.(SEMBOL)
C2: Yüklenmedi | D2: Yolda | E2: Limanda | F2: Antrepoda | AA2: W.CASHEW NUT W240 KAV.(STAR)
B3: LIEN VIET | C3: =COUNTIFS('SATIN ALMA'!$F:$F, $B3, 'SATIN ALMA'!$AB:$AB, C$2) -> 0 | D3: =COUNTIFS('SATIN ALMA'!$F:$F, $B3, 'SATIN ALMA'!$AB:$AB, D$2) -> 9 | E3: =COUNTIFS('SATIN ALMA'!$F:$F, $B3, 'SATIN ALMA'!$AB:$AB, E$2) -> 6 | F3: =COUNTIFS('SATIN ALMA'!$F:$F, $B3, 'SATIN ALMA'!$AB:$AB, F$2) -> 4 | AA3: W.CASHEW NUT W320 KAVR (BUNGEE)
B4: MANH TUAN | C4: =COUNTIFS('SATIN ALMA'!$F:$F, $B4, 'SATIN ALMA'!$AB:$AB, C$2) -> 0 | D4: =COUNTIFS('SATIN ALMA'!$F:$F, $B4, 'SATIN ALMA'!$AB:$AB, D$2) -> 0 | E4: =COUNTIFS('SATIN ALMA'!$F:$F, $B4, 'SATIN ALMA'!$AB:$AB, E$2) -> 2 | F4: =COUNTIFS('SATIN ALMA'!$F:$F, $B4, 'SATIN ALMA'!$AB:$AB, F$2) -> 2
B5: NGAN NGOC | C5: =COUNTIFS('SATIN ALMA'!$F:$F, $B5, 'SATIN ALMA'!$AB:$AB, C$2) -> 0 | D5: =COUNTIFS('SATIN ALMA'!$F:$F, $B5, 'SATIN ALMA'!$AB:$AB, D$2) -> 1 | E5: =COUNTIFS('SATIN ALMA'!$F:$F, $B5, 'SATIN ALMA'!$AB:$AB, E$2) -> 0 | F5: =COUNTIFS('SATIN ALMA'!$F:$F, $B5, 'SATIN ALMA'!$AB:$AB, F$2) -> 2
B6: TRU LANH | C6: =COUNTIFS('SATIN ALMA'!$F:$F, $B6, 'SATIN ALMA'!$AB:$AB, C$2) -> 0 | D6: =COUNTIFS('SATIN ALMA'!$F:$F, $B6, 'SATIN ALMA'!$AB:$AB, D$2) -> 0 | E6: =COUNTIFS('SATIN ALMA'!$F:$F, $B6, 'SATIN ALMA'!$AB:$AB, E$2) -> 0 | F6: =COUNTIFS('SATIN ALMA'!$F:$F, $B6, 'SATIN ALMA'!$AB:$AB, F$2) -> 2
B7: VINH PHUONG | C7: =COUNTIFS('SATIN ALMA'!$F:$F, $B7, 'SATIN ALMA'!$AB:$AB, C$2) -> 0 | D7: =COUNTIFS('SATIN ALMA'!$F:$F, $B7, 'SATIN ALMA'!$AB:$AB, D$2) -> 1 | E7: =COUNTIFS('SATIN ALMA'!$F:$F, $B7, 'SATIN ALMA'!$AB:$AB, E$2) -> 0 | F7: =COUNTIFS('SATIN ALMA'!$F:$F, $B7, 'SATIN ALMA'!$AB:$AB, F$2) -> 0 | AA7: HW.CASHEW NUT W320____________( 22.68 KG )
B8: CAO PHAT | C8: =COUNTIFS('SATIN ALMA'!$F:$F, $B8, 'SATIN ALMA'!$AB:$AB, C$2) -> 0 | D8: =COUNTIFS('SATIN ALMA'!$F:$F, $B8, 'SATIN ALMA'!$AB:$AB, D$2) -> 1 | E8: =COUNTIFS('SATIN ALMA'!$F:$F, $B8, 'SATIN ALMA'!$AB:$AB, E$2) -> 0 | F8: =COUNTIFS('SATIN ALMA'!$F:$F, $B8, 'SATIN ALMA'!$AB:$AB, F$2) -> 0 | AA8: HW.CASHEW NUT W240____________( 22.68 KG )
B9: TOPLAM | C9: =SUM(C3:C8) -> 0 | D9: =SUM(D3:D8) -> 12 | E9: =SUM(E3:E8) -> 8 | F9: =SUM(F3:F8) -> 10 | AA9: HW.CASHEW NUT W180____________( 22.68 KG )
C11: Yüklenmedi | D11: Yolda | E11: Limanda | F11: Antrepoda | I11: Eski Fiyat | J11: Güncel Fiyat | M11: Beklenen | N11: Antrepo | O11: Depo
B12: WW320 | C12: =COUNTIFS('SATIN ALMA'!$G:$G, $B12, 'SATIN ALMA'!$AB:$AB, C$11) -> 0 | D12: =COUNTIFS('SATIN ALMA'!$G:$G, $B12, 'SATIN ALMA'!$AB:$AB, D$11) -> 6 | E12: =COUNTIFS('SATIN ALMA'!$G:$G, $B12, 'SATIN ALMA'!$AB:$AB, E$11) -> 8 | F12: =COUNTIFS('SATIN ALMA'!$G:$G, $B12, 'SATIN ALMA'!$AB:$AB, F$11) -> 9 | H12: WW320 | I12: 3.14 | J12: 3.24 | L12: WW320 | M12: 24948 | N12: 59622 | O12: 0
B13: WW240 | C13: =COUNTIFS('SATIN ALMA'!$G:$G, $B13, 'SATIN ALMA'!$AB:$AB, C$11) -> 0 | D13: =COUNTIFS('SATIN ALMA'!$G:$G, $B13, 'SATIN ALMA'!$AB:$AB, D$11) -> 4 | E13: =COUNTIFS('SATIN ALMA'!$G:$G, $B13, 'SATIN ALMA'!$AB:$AB, E$11) -> 0 | F13: =COUNTIFS('SATIN ALMA'!$G:$G, $B13, 'SATIN ALMA'!$AB:$AB, F$11) -> 0 | H13: WW240 | I13: 3.2 | J13: 3.1 | L13: WW240 | M13: 59486 | N13: 25111 | O13: 0
B14: WW180 | C14: =COUNTIFS('SATIN ALMA'!$G:$G, $B14, 'SATIN ALMA'!$AB:$AB, C$11) -> 0 | D14: =COUNTIFS('SATIN ALMA'!$G:$G, $B14, 'SATIN ALMA'!$AB:$AB, D$11) -> 2 | E14: =COUNTIFS('SATIN ALMA'!$G:$G, $B14, 'SATIN ALMA'!$AB:$AB, E$11) -> 0 | F14: =COUNTIFS('SATIN ALMA'!$G:$G, $B14, 'SATIN ALMA'!$AB:$AB, F$11) -> 1 | H14: WW180 | I14: 3.9 | J14: 4.5 | L14: WW180 | M14: 146500 | N14: 15984 | O14: 0
B15: TOPLAM | C15: =SUM(C12:C14) -> 0 | D15: =SUM(D12:D14) -> 12 | E15: =SUM(E12:E14) -> 8 | F15: =SUM(F12:F14) -> 10 | H15: + | L15: +
AB16: WW320 | AC16: WW240 | AD16: WW180
B17: Tarih Aralığı | C17: 11/09/24-23/09/25 | AA17: Sayım | AB17: =COUNTIF('SATIN ALMA'!$G:$G,AB16) -> 50 | AC17: =COUNTIF('SATIN ALMA'!$G:$G,AC16) -> 12 | AD17: =COUNTIF('SATIN ALMA'!$G:$G,AD16) -> 3
C18: WW320 | D18: WW240 | E18: WW180 | AA18: Fiyat Toplam | AB18: =SUMIF('SATIN ALMA'!$G:$G,AB16,'SATIN ALMA'!$J:$J) -> 161.49 | AC18: =SUMIF('SATIN ALMA'!$G:$G,AC16,'SATIN ALMA'!$J:$J) -> 41.02 | AD18: =SUMIF('SATIN ALMA'!$G:$G,AD16,'SATIN ALMA'!$J:$J) -> 11.1
B19: Ortalama Fiyat | C19: =AB19 -> 3.2298 | D19: =AC19 -> 3.4183333 | E19: =AD19 -> 3.7 | AA19: Ortalama | AB19: =AB18/AB17 -> 3.2298 | AC19: =AC18/AC17 -> 3.4183333 | AD19: =AD18/AD17 -> 3.7

Sheet SATIN ALMA
A1: Sipariş Tarihi | B1: REF | C1: Stok Kodu | D1: Stok Adı | E1: Seller | F1: Shipper | G1: Product | H1: Crop | I1: Packaging | J1: FOB Price | K1: Freight Per LB | L1: CNF PRICE | M1: Freight | N1: Quantity LB | O1: Quantity KG | P1: TYPE | Q1: FCL | R1: Konteyner No | S1: Antrepo Bey. No | T1: B/L No | U1: Booking No | V1: Ref. No. | W1: Contract | X1: Tır No. | Y1: ETD | Z1: ETA | AA1: Transit | AB1: Manuel Seçilecek
A2: 45546 | B2: 581344 | C2: H5130003 | D2: =IF(C2="H5130003","HW.CASHEW NUT W320____________( 22.68 KG )",IF(C2="H5130001","HW.CASHEW NUT W240____________( 22.68 KG )",IF(C2="H5130164","HW.CASHEW NUT W180____________( 22.68 KG )",""))) -> HW.CASHEW NUT W320____________( 22.68 KG ) | E2: HD CASHEW | F2: NGOC DIEP | G2: WW320 | H2: 2024 | I2: FLEXIPACKS | J2: 3.22 | K2: =M2/N2 -> 0.081818182 | L2: =K2+J2 -> 3.3018182 | M2: 4500 | N2: 55000 | O2: =N2*0.4536 -> 24948 | P2: 40 | Q2: 1 | R2: MSDU4120180 | T2: MEDUH8009944 | V2: 25031-IT25154013 | W2: HD46411 | X2: =IFERROR(INDEX('GİRİŞ ANALİZİ'!$D:$D, MATCH($W2,'GİRİŞ ANALİZİ'!$B:$B, 0)),"Bulunamadı") -> 2 | Y2: 45564 | Z2: 45610 | AA2: =Z2-Y2 -> 46 | AB2: İçeri Çekildi | AD2: Yüklenmedi
A3: 45546 | B3: 581345 | C3: H5130003 | D3: =IF(C3="H5130003","HW.CASHEW NUT W320____________( 22.68 KG )",IF(C3="H5130001","HW.CASHEW NUT W240____________( 22.68 KG )",IF(C3="H5130164","HW.CASHEW NUT W180____________( 22.68 KG )",""))) -> HW.CASHEW NUT W320____________( 22.68 KG ) | E3: HD CASHEW | F3: MANH TUAN | G3: WW320 | H3: 2024 | I3: FLEXIPACKS | J3: 3.25 | K3: =M3/N3 -> 0.081818182 | L3: =K3+J3 -> 3.3318182 | M3: 4500 | N3: 55000 | O3: =N3*0.4536 -> 24948 | P3: 40 | Q3: 1 | R3: MSDU4566450 | T3: MEDUOE948114 | V3: 25032-IT25154014 | W3: HD46511 | X3: =IFERROR(INDEX('GİRİŞ ANALİZİ'!$D:$D, MATCH($W3,'GİRİŞ ANALİZİ'!$B:$B, 0)),"Bulunamadı") -> 1 | Y3: 45558 | Z3: 45610 | AA3: =Z3-Y3 -> 52 | AB3: İçeri Çekildi | AD3: Yolda
A4: 45546 | B4: 581342 | C4: H5130003 | D4: =IF(C4="H5130003","HW.CASHEW NUT W320____________( 22.68 KG )",IF(C4="H5130001","HW.CASHEW NUT W240____________( 22.68 KG )",IF(C4="H5130164","HW.CASHEW NUT W180____________( 22.68 KG )",""))) -> HW.CASHEW NUT W320____________( 22.68 KG ) | E4: HD CASHEW | F4: NGAN NGOC | G4: WW320 | H4: 2024 | I4: FLEXIPACKS | J4: 3.22 | K4: =M4/N4 -> 0.081818182 | L4: =K4+J4 -> 3.3018182 | M4: 4500 | N4: 55000 | O4: =N4*0.4536 -> 24948 | P4: 40 | Q4: 1 | R4: MSDU4309929 | T4: MEDUOE979309 | V4: 25030-IT25154012 | W4: HD46311 | X4: =IFERROR(INDEX('GİRİŞ ANALİZİ'!$D:$D, MATCH($W4,'GİRİŞ ANALİZİ'!$B:$B, 0)),"Bulunamadı") -> Bulunamadı | Y4: 45569 | Z4: 45616 | AA4: =Z4-Y4 -> 47 | AB4: İçeri Çekildi | AD4: Antrepoda
A5: 45577 | B5: 588102 | C5: H5130003 | D5: =IF(C5="H5130003","HW.CASHEW NUT W320____________( 22.68 KG )",IF(C5="H5130001","HW.CASHEW NUT W240____________( 22.68 KG )",IF(C5="H5130164","HW.CASHEW NUT W180____________( 22.68 KG )",""))) -> HW.CASHEW NUT W320____________( 22.68 KG ) | E5: HD CASHEW | F5: NGAN NGOC | G5: WW320 | H5: 2024 | I5: FLEXIPACKS | J5: 3.27 | K5: =M5/N5 -> 0.065454545 | L5: =K5+J5 -> 3.3354545 | M5: 3600 | N5: 55000 | O5: =N5*0.4536 -> 24948 | P5: 40 | Q5: 1 | R5: MSDU4165400 | T5: MEDUH8104836 | V5: 25070-IT25154033 | W5: HD49711 | X5: =IFERROR(INDEX('GİRİŞ ANALİZİ'!$D:$D, MATCH($W5,'GİRİŞ ANALİZİ'!$B:$B, 0)),"Bulunamadı") -> 4 | Y5: 45578 | Z5: 45628 | AA5: =Z5-Y5 -> 50 | AB5: İçeri Çekildi | AD5: İçeri Çekildi
A6: 45562 | B6: 585022 | C6: H5130003 | D6: =IF(C6="H5130003","HW.CASHEW NUT W320____________( 22.68 KG )",IF(C6="H5130001","HW.CASHEW NUT W240____________( 22.68 KG )",IF(C6="H5130164","HW.CASHEW NUT W180____________( 22.68 KG )",""))) -> HW.CASHEW NUT W320____________( 22.68 KG ) | E6: HD CASHEW | F6: MANH TUAN | G6: WW320 | H6: 2024 | I6: FLEXIPACKS | J6: 3.25 | K6: =M6/N6 -> 0.065454545 | L6: =K6+J6 -> 3.3154545 | M6: 3600 | N6: 55000 | O6: =N6*0.4536 -> 24948 | P6: 40 | Q6: 1 | R6: MSCU4794435 | T6: MEDUH8121087 | V6: 25064-IT25154031 | W6: HD48511 | X6: =IFERROR(INDEX('GİRİŞ ANALİZİ'!$D:$D, MATCH($W6,'GİRİŞ ANALİZİ'!$B:$B, 0)),"Bulunamadı") -> 5 | Y6: 45585 | Z6: 45636 | AA6: =Z6-Y6 -> 51 | AB6: İçeri Çekildi | AD6: Limanda
A7: 45577 | B7: 588103 | C7: H5130003 | D7: =IF(C7="H5130003","HW.CASHEW NUT W320____________( 22.68 KG )",IF(C7="H5130001","HW.CASHEW NUT W240____________( 22.68 KG )",IF(C7="H5130164","HW.CASHEW NUT W180____________( 22.68 KG )",""))) -> HW.CASHEW NUT W320____________( 22.68 KG ) | E7: HD CASHEW | F7: NGAN NGOC | G7: WW320 | H7: 2024 | I7: FLEXIPACKS | J7: 3.32 | K7: =M7/N7 -> 0.065454545 | L7: =K7+J7 -> 3.3854545 | M7: 3600 | N7: 55000 | O7: =N7*0.4536 -> 24948 | P7: 40 | Q7: 1 | R7: MSDU4622173 | T7: MEDUH8157990 | V7: 25074-IT25154034 | W7: HD50811-01 | X7: =IFERROR(INDEX('GİRİŞ ANALİZİ'!$D:$D, MATCH($W7,'GİRİŞ ANALİZİ'!$B:$B, 0)),"Bulunamadı") -> 6 | Y7: 45588 | Z7: 45636 | AA7: =Z7-Y7 -> 48 | AB7: İçeri Çekildi | AD7: GÜNCELLEME TARİHİ:
A8: 45562 | B8: 585005 | C8: H5130001 | D8: =IF(C8="H5130003","HW.CASHEW NUT W320____________( 22.68 KG )",IF(C8="H5130001","HW.CASHEW NUT W240____________( 22.68 KG )",IF(C8="H5130164","HW.CASHEW NUT W180____________( 22.68 KG )",""))) -> HW.CASHEW NUT W240____________( 22.68 KG ) | E8: HD CASHEW | F8: MANH TUAN | G8: WW240 | H8: 2024 | I8: FLEXIPACKS | J8: 3.6 | K8: =M8/N8 -> 0.065454545 | L8: =K8+J8 -> 3.6654545 | M8: 3600 | N8: 55000 | O8: =N8*0.4536 -> 24948 | P8: 40 | Q8: 1 | R8: MSDU4618419 | T8: MEDUH8156158 | V8: 25051-IT25154023 | W8: HD47411 | X8: 8 | Y8: 45588 | Z8: 45656 | AA8: =Z8-Y8 -> 68 | AB8: İçeri Çekildi
A9: 45638 | B9: 588103 | C9: H5130003 | D9: =IF(C9="H5130003","HW.CASHEW NUT W320____________( 22.68 KG )",IF(C9="H5130001","HW.CASHEW NUT W240____________( 22.68 KG )",IF(C9="H5130164","HW.CASHEW NUT W180____________( 22.68 KG )",""))) -> HW.CASHEW NUT W320____________( 22.68 KG ) | E9: HD CASHEW | F9: NGAN NGOC | G9: WW320 | H9: 2024 | I9: FLEXIPACKS | J9: 3.32 | K9: =M9/N9 -> 0.065454545 | L9: =K9+J9 -> 3.3854545 | M9: 3600 | N9: 55000 | O9: =N9*0.4536 -> 24948 | P9: 40 | Q9: 1 | R9: MSDU4170601 | T9: MEDUH8220780 | V9: 25074-IT25154034 | W9: HD50811-02 | X9: =IFERROR(INDEX('GİRİŞ ANALİZİ'!$D:$D, MATCH($W9,'GİRİŞ ANALİZİ'!$B:$B, 0)),"Bulunamadı") -> 7 | Y9: 45600 | Z9: 45656 | AA9: =Z9-Y9 -> 56 | AB9: İçeri Çekildi
A10: 45638 | B10: 588103 | C10: H5130003 | D10: =IF(C10="H5130003","HW.CASHEW NUT W320____________( 22.68 KG )",IF(C10="H5130001","HW.CASHEW NUT W240____________( 22.68 KG )",IF(C10="H5130164","HW.CASHEW NUT W180____________( 22.68 KG )",""))) -> HW.CASHEW NUT W320____________( 22.68 KG ) | E10: HD CASHEW | F10: NGAN NGOC | G10: WW320 | H10: 2024 | I10: FLEXIPACKS | J10: 3.32 | K10: =M10/N10 -> 0.084 | L10: =K10+J10 -> 3.404 | M10: 4620 | N10: 55000 | O10: =N10*0.4536 -> 24948 | P10: 40 | Q10: 1 | R10: MEDU4183366 | T10: MEDUH8248658 | V10: 25074-IT25154034 | W10: HD50811-03 | X10: =IFERROR(INDEX('GİRİŞ ANALİZİ'!$D:$D, MATCH($W10,'GİRİŞ ANALİZİ'!$B:$B, 0)),"Bulunamadı") -> 10 | Y10: 45602 | Z10: 45656 | AA10: =Z10-Y10 -> 54 | AB10: İçeri Çekildi | AD10: 45993
A11: 45626 | B11: 596417 | C11: H5130003 | D11: =IF(C11="H5130003","HW.CASHEW NUT W320____________( 22.68 KG )",IF(C11="H5130001","HW.CASHEW NUT W240____________( 22.68 KG )",IF(C11="H5130164","HW.CASHEW NUT W180____________( 22.68 KG )",""))) -> HW.CASHEW NUT W320____________( 22.68 KG ) | E11: HD CASHEW | F11: MANH TUAN | G11: WW320 | H11: 2024 | I11: FLEXIPACKS | J11: 3.5 | K11: =M11/N11 -> 0.10636364 | L11: =K11+J11 -> 3.6063636 | M11: 5850 | N11: 55000 | O11: =N11*0.4536 -> 24948 | P11: 40 | Q11: 1 | R11: MSDU4495422 | T11: MEDUH8403261 | U11: EBKG10883487 | V11: 25132-IT25154096 | W11: HD55711-01 | X11: =IFERROR(INDEX('GİRİŞ ANALİZİ'!$D:$D, MATCH($W11,'GİRİŞ ANALİZİ'!$B:$B, 0)),"Bulunamadı") -> 11 | Y11: 45627 | Z11: 45677 | AA11: =Z11-Y11 -> 50 | AB11: İçeri Çekildi
A12: 45626 | B12: 596417 | C12: H5130003 | D12: =IF(C12="H5130003","HW.CASHEW NUT W320____________( 22.68 KG )",IF(C12="H5130001","HW.CASHEW NUT W240____________( 22.68 KG )",IF(C12="H5130164","HW.CASHEW NUT W180____________( 22.68 KG )",""))) -> HW.CASHEW NUT W320____________( 22.68 KG ) | E12: HD CASHEW | F12: MANH TUAN | G12: WW320 | H12: 2024 | I12: FLEXIPACKS | J12: 3.5 | K12: =M12/N12 -> 0.12454545 | L12: =K12+J12 -> 3.6245455 | M12: 6850 | N12: 55000 | O12: =N12*0.4536 -> 24948 | P12: 40 | Q12: 1 | R12: MSDU4727580 | T12: MEDUH8462408 | U12: EBKG10995144 | V12: 25132-IT25154096 | W12: HD55711-02 | X12: =IFERROR(INDEX('GİRİŞ ANALİZİ'!$D:$D, MATCH($W12,'GİRİŞ ANALİZİ'!$B:$B, 0)),"Bulunamadı") -> 12 | Y12: 45643 | Z12: 45692 | AA12: =Z12-Y12 -> 49 | AB12: İçeri Çekildi
A13: 45626 | B13: 596418 | C13: H5130001 | D13: =IF(C13="H5130003","HW.CASHEW NUT W320____________( 22.68 KG )",IF(C13="H5130001","HW.CASHEW NUT W240____________( 22.68 KG )",IF(C13="H5130164","HW.CASHEW NUT W180____________( 22.68 KG )",""))) -> HW.CASHEW NUT W240____________( 22.68 KG ) | E13: HD CASHEW | F13: MANH TUAN | G13: WW240 | H13: 2024 | I13: FLEXIPACKS | J13: 3.7 | K13: =M13/N13 -> 0.12454545 | L13: =K13+J13 -> 3.8245455 | M13: 6850 | N13: 55000 | O13: =N13*0.4536 -> 24948 | P13: 40 | Q13: 1 | R13: MSDU4390756 | T13: MEDUH8462416 | V13: 25147-IT25154097 | W13: HD56811 | X13: 13 | Y13: 45644 | Z13: 45692 | AA13: =Z13-Y13 -> 48 | AB13: İçeri Çekildi
A14: 45677 | B14: 604842 | C14: H5130001 | D14: =IF(C14="H5130003","HW.CASHEW NUT W320____________( 22.68 KG )",IF(C14="H5130001","HW.CASHEW NUT W240____________( 22.68 KG )",IF(C14="H5130164","HW.CASHEW NUT W180____________( 22.68 KG )",""))) -> HW.CASHEW NUT W240____________( 22.68 KG ) | E14: HD CASHEW | F14: NGAN NGOC | G14: WW240 | H14: 2024 | I14: FLEXIPACKS | J14: 3.68 | K14: =M14/N14 -> 0.12454545 | L14: =K14+J14 -> 3.8045455 | M14: 6850 | N14: 55000 | O14: =N14*0.4536 -> 24948 | P14: 40 | Q14: 1 | R14: MSDU4403560 | T14: MEDUHP005737 | V14: 25155-IT25154137 | W14: HD57711 | X14: 14 | Y14: 45644 | Z14: 45692 | AA14: =Z14-Y14 -> 48 | AB14: İçeri Çekildi
A15: 45677 | B15: 604850 | C15: H5130001 | D15: =IF(C15="H5130003","HW.CASHEW NUT W320____________( 22.68 KG )",IF(C15="H5130001","HW.CASHEW NUT W240____________( 22.68 KG )",IF(C15="H5130164","HW.CASHEW NUT W180____________( 22.68 KG )",""))) -> HW.CASHEW NUT W240____________( 22.68 KG ) | E15: HD CASHEW | F15: MANH TUAN | G15: WW240 | H15: 2024 | I15: FLEXIPACKS | J15: 3.62 | K15: =M15/N15 -> 0.11636364 | L15: =K15+J15 -> 3.7363636 | M15: 6400 | N15: 55000 | O15: =N15*0.4536 -> 24948 | P15: 40 | Q15: 1 | R15: MSDU4811541 | T15: MEDUHP199142 | V15: 25172-IT25154132 | W15: HD59111 | X15: 15 | Y15: 45679 | Z15: 45729 | AA15: =Z15-Y15 -> 50 | AB15: İçeri Çekildi
A16: 45677 | B16: 604854 | C16: H5130001 | D16: =IF(C16="H5130003","HW.CASHEW NUT W320____________( 22.68 KG )",IF(C16="H5130001","HW.CASHEW NUT W240____________( 22.68 KG )",IF(C16="H5130164","HW.CASHEW NUT W180____________( 22.68 KG )",""))) -> HW.CASHEW NUT W240____________( 22.68 KG ) | E16: HD CASHEW | F16: TRU LANH | G16: WW240 | H16: 2024 | I16: FLEXIPACKS | J16: 3.6 | K16: =M16/N16 -> 0.11636364 | L16: =K16+J16 -> 3.7163636 | M16: 6400 | N16: 55000 | O16: =N16*0.4536 -> 24948 | P16: 40 | Q16: 1 | R16: TTNU5156838 | T16: MEDUHP196163 | V16: 25173-IT25154131 | W16: HD59211 | X16: 16 | Y16: 45679 | Z16: 45729 | AA16: =Z16-Y16 -> 50 | AB16: İçeri Çekildi
A17: 45719 | B17: 611081 | C17: H5130003 | D17: =IF(C17="H5130003","HW.CASHEW NUT W320____________( 22.68 KG )",IF(C17="H5130001","HW.CASHEW NUT W240____________( 22.68 KG )",IF(C17="H5130164","HW.CASHEW NUT W180____________( 22.68 KG )",""))) -> HW.CASHEW NUT W320____________( 22.68 KG ) | E17: HD CASHEW | F17: NGAN NGOC | G17: WW320 | H17: 2024 | I17: FLEXIPACKS | J17: 3.22 | K17: =M17/N17 -> 0.078363636 | L17: =K17+J17 -> 3.2983636 | M17: 4310 | N17: 55000 | O17: =N17*0.4536 -> 24948 | P17: 40 | Q17: 1 | R17: MSDU4130928 | T17: MEDUHP428095 | V17: 25206-IT25154154 | W17: HD05312-01 | X17: =IFERROR(INDEX('GİRİŞ ANALİZİ'!$D:$D, MATCH($W17,'GİRİŞ ANALİZİ'!$B:$B, 0)),"Bulunamadı") -> 17 | Y17: 45726 | Z17: 45771 | AA17: =Z17-Y17 -> 45 | AB17: İçeri Çekildi
A18: 45707 | B18: 609356 | C18: H5130003 | D18: =IF(C18="H5130003","HW.CASHEW NUT W320____________( 22.68 KG )",IF(C18="H5130001","HW.CASHEW NUT W240____________( 22.68 KG )",IF(C18="H5130164","HW.CASHEW NUT W180____________( 22.68 KG )",""))) -> HW.CASHEW NUT W320____________( 22.68 KG ) | E18: HD CASHEW | F18: NGOC DIEP | G18: WW320 | H18: 2024 | I18: FLEXIPACKS | J18: 3.21 | K18: =M18/N18 -> 0.071090909 | L18: =K18+J18 -> 3.2810909 | M18: 3910 | N18: 55000 | O18: =N18*0.4536 -> 24948 | P18: 40 | Q18: 1 | R18: MSDU4560106 | T18: MEDUHP449844 | V18: 25196-IT25154149 | W18: HD03012 | X18: =IFERROR(INDEX('GİRİŞ ANALİZİ'!$D:$D, MATCH($W18,'GİRİŞ ANALİZİ'!$B:$B, 0)),"Bulunamadı") -> 18 | Y18: 45740 | Z18: 45793 | AA18: =Z18-Y18 -> 53 | AB18: İçeri Çekildi
A19: 45769 | B19: 619479 | C19: H5130003 | D19: =IF(C19="H5130003","HW.CASHEW NUT W320____________( 22.68 KG )",IF(C19="H5130001","HW.CASHEW NUT W240____________( 22.68 KG )",IF(C19="H5130164","HW.CASHEW NUT W180____________( 22.68 KG )",""))) -> HW.CASHEW NUT W320____________( 22.68 KG ) | E19: HD CASHEW | F19: LIEN VIET | G19: WW320 | H19: 2025 | I19: FLEXIPACKS | J19: 3.3 | K19: =M19/N19 -> 0.054545455 | L19: =K19+J19 -> 3.3545455 | M19: 3000 | N19: 55000 | O19: =N19*0.4536 -> 24948 | P19: 40 | Q19: 1 | R19: MSBU4032987 | T19: MEDUHQ071050 | V19: 25242-IT25154178 | W19: HD20912-1 | X19: =IFERROR(INDEX('GİRİŞ ANALİZİ'!$D:$D, MATCH($W19,'GİRİŞ ANALİZİ'!$B:$B, 0)),"Bulunamadı") -> 19 | Y19: 45779 | Z19: 45834 | AA19: =Z19-Y19 -> 55 | AB19: İçeri Çekildi
A20: 45769 | B20: 619479 | C20: H5130001 | D20: =IF(C20="H5130003","HW.CASHEW NUT W320____________( 22.68 KG )",IF(C20="H5130001","HW.CASHEW NUT W240____________( 22.68 KG )",IF(C20="H5130164","HW.CASHEW NUT W180____________( 22.68 KG )",""))) -> HW.CASHEW NUT W240____________( 22.68 KG ) | E20: HD CASHEW | F20: LIEN VIET | G20: WW240 | H20: 2025 | I20: FLEXIPACKS | J20: 3.4 | K20: =M20/N20 -> 0.054545455 | L20: =K20+J20 -> 3.4545455 | M20: 3000 | N20: =Q20*55000 -> 55000 | O20: =N20*0.4536 -> 24948 | P20: 40 | Q20: 1 | R20: MSDU4296014 | S20: AN00025929 | T20: MEDUHQ070235 | V20: 25242-IT25154178 | W20: HD21012 | X20: =IFERROR(INDEX('GİRİŞ ANALİZİ'!$D:$D, MATCH($W20,'GİRİŞ ANALİZİ'!$B:$B, 0)),"Bulunamadı") -> 20 | Y20: 45782 | Z20: 45842 | AA20: =Z20-Y20 -> 60 | AB20: İçeri Çekildi
A21: 45769 | B21: 619479 | C21: H5130003 | D21: =IF(C21="H5130003","HW.CASHEW NUT W320____________( 22.68 KG )",IF(C21="H5130001","HW.CASHEW NUT W240____________( 22.68 KG )",IF(C21="H5130164","HW.CASHEW NUT W180____________( 22.68 KG )",""))) -> HW.CASHEW NUT W320____________( 22.68 KG ) | E21: HD CASHEW | F21: LIEN VIET | G21: WW320 | H21: 2025 | I21: FLEXIPACKS | J21: 3.3 | K21: =M21/N21 -> 0.062727273 | L21: =K21+J21 -> 3.3627273 | M21: 3450 | N21: 55000 | O21: =N21*0.4536 -> 24948 | P21: 40 | Q21: 1 | R21: MSDU4414349 | S21: AN00028332 | T21: MEDUHQ178665 | V21: 25242-IT25154178 | W21: HD20912-3 | X21: =IFERROR(INDEX('GİRİŞ ANALİZİ'!$D:$D, MATCH($W21,'GİRİŞ ANALİZİ'!$B:$B, 0)),"Bulunamadı") -> 22 | Y21: 45806 | Z21: 45862 | AA21: =Z21-Y21 -> 56 | AB21: İçeri Çekildi
A22: 45769 | B22: 619479 | C22: H5130003 | D22: =IF(C22="H5130003","HW.CASHEW NUT W320____________( 22.68 KG )",IF(C22="H5130001","HW.CASHEW NUT W240____________( 22.68 KG )",IF(C22="H5130164","HW.CASHEW NUT W180____________( 22.68 KG )",""))) -> HW.CASHEW NUT W320____________( 22.68 KG ) | E22: HD CASHEW | F22: LIEN VIET | G22: WW320 | H22: 2025 | I22: FLEXIPACKS | J22: 3.3 | K22: =M22/N22 -> 0.062727273 | L22: =K22+J22 -> 3.3627273 | M22: 3450 | N22: 55000 | O22: =N22*0.4536 -> 24948 | P22: 40 | Q22: 1 | R22: FSCU4854692 | S22: AN00028332 | T22: MEDUHQ178665 | V22: 25242-IT25154178 | W22: HD20912-2 | X22: =IFERROR(INDEX('GİRİŞ ANALİZİ'!$D:$D, MATCH($W22,'GİRİŞ ANALİZİ'!$B:$B, 0)),"Bulunamadı") -> 21 | Y22: 45806 | Z22: 45862 | AA22: =Z22-Y22 -> 56 | AB22: İçeri Çekildi
A23: 45803 | B23: 625591 | C23: H5130003 | D23: =IF(C23="H5130003","HW.CASHEW NUT W320____________( 22.68 KG )",IF(C23="H5130001","HW.CASHEW NUT W240____________( 22.68 KG )",IF(C23="H5130164","HW.CASHEW NUT W180____________( 22.68 KG )",""))) -> HW.CASHEW NUT W320____________( 22.68 KG ) | E23: HD CASHEW | F23: LIEN VIET | G23: WW320 | H23: 2025 | I23: FLEXIPACKS | J23: 3.27 | K23: =M23/N23 -> 0.062727273 | L23: =K23+J23 -> 3.3327273 | M23: 3450 | N23: =Q23*55000 -> 55000 | O23: =N23*0.4536 -> 24948 | P23: 40 | Q23: 1 | R23: SEGU6899150 | T23: 15098281 | U23: DSV0990402 | V23: 25261-IT25154191 | W23: HD29312-1 | X23: =IFERROR(INDEX('GİRİŞ ANALİZİ'!$D:$D, MATCH($W23,'GİRİŞ ANALİZİ'!$B:$B, 0)),"Bulunamadı") -> 23 | Y23: 45817 | Z23: 45865 | AA23: =Z23-Y23 -> 48 | AB23: İçeri Çekildi
A24: 45803 | B24: 625591 | C24: H5130003 | D24: =IF(C24="H5130003","HW.CASHEW NUT W320____________( 22.68 KG )",IF(C24="H5130001","HW.CASHEW NUT W240____________( 22.68 KG )",IF(C24="H5130164","HW.CASHEW NUT W180____________( 22.68 KG )",""))) -> HW.CASHEW NUT W320____________( 22.68 KG ) | E24: HD CASHEW | F24: LIEN VIET | G24: WW320 | H24: 2025 | I24: FLEXIPACKS | J24: 3.27 | K24: =M24/N24 -> 0.092727273 | L24: =K24+J24 -> 3.3627273 | M24: 5100 | N24: 55000 | O24: =N24*0.4536 -> 24948 | P24: 40 | Q24: 1 | R24: HAMU4093393 | S24: AN00029898 | T24: 18717647 | U24: DSV0991421 | V24: 25261-IT25154191 | W24: HD29312-2 | X24: =IFERROR(INDEX('GİRİŞ ANALİZİ'!$D:$D, MATCH($W24,'GİRİŞ ANALİZİ'!$B:$B, 0)),"Bulunamadı") -> 24 | Y24: 45826 | Z24: 45872 | AA24: =Z24-Y24 -> 46 | AB24: İçeri Çekildi
A25: 45803 | B25: 625591 | C25: H5130003 | D25: =IF(C25="H5130003","HW.CASHEW NUT W320____________( 22.68 KG )",IF(C25="H5130001","HW.CASHEW NUT W240____________( 22.68 KG )",IF(C25="H5130164","HW.CASHEW NUT W180____________( 22.68 KG )",""))) -> HW.CASHEW NUT W320____________( 22.68 KG ) | E25: HD CASHEW | F25: LIEN VIET | G25: WW320 | H25: 2025 | I25: FLEXIPACKS | J25: 3.27 | K25: =M25/N25 -> 0.092727273 | L25: =K25+J25 -> 3.3627273 | M25: 5100 | N25: 55000 | O25: =N25*0.4536 -> 24948 | P25: 40 | Q25: 1 | R25: UETU5170212 | S25: AN00029898 | T25: 18717647 | U25: DSV0991421 | V25: 25261-IT25154191 | W25: HD29312-3 | X25: =IFERROR(INDEX('GİRİŞ ANALİZİ'!$D:$D, MATCH($W25,'GİRİŞ ANALİZİ'!$B:$B, 0)),"Bulunamadı") -> 25 | Y25: 45826 | Z25: 45872 | AA25: =Z25-Y25 -> 46 | AB25: İçeri Çekildi
A26: 45803 | B26: 625597 | C26: H5130003 | D26: =IF(C26="H5130003","HW.CASHEW NUT W320____________( 22.68 KG )",IF(C26="H5130001","HW.CASHEW NUT W240____________( 22.68 KG )",IF(C26="H5130164","HW.CASHEW NUT W180____________( 22.68 KG )",""))) -> HW.CASHEW NUT W320____________( 22.68 KG ) | E26: HD CASHEW | F26: MANH TUAN | G26: WW320 | H26: 2025 | I26: FLEXIPACKS | J26: 3.27 | K26: =M26/N26 -> 0.087272727 | L26: =K26+J26 -> 3.3572727 | M26: 4800 | N26: =Q26*55000 -> 55000 | O26: =N26*0.4536 -> 24948 | P26: 40 | Q26: 1 | R26: MSBU4047729 | T26: MEDUHQ437863 | U26: EBKG13297042 | V26: 25258-IT25154192 | W26: HD29612-1 | X26: =IFERROR(INDEX('GİRİŞ ANALİZİ'!$D:$D, MATCH($W26,'GİRİŞ ANALİZİ'!$B:$B, 0)),"Bulunamadı") -> 26 | Y26: 45830 | Z26: 45879 | AA26: =Z26-Y26 -> 49 | AB26: İçeri Çekildi
A27: 45803 | B27: 625597 | C27: H5130003 | D27: =IF(C27="H5130003","HW.CASHEW NUT W320____________( 22.68 KG )",IF(C27="H5130001","HW.CASHEW NUT W240____________( 22.68 KG )",IF(C27="H5130164","HW.CASHEW NUT W180____________( 22.68 KG )",""))) -> HW.CASHEW NUT W320____________( 22.68 KG ) | E27: HD CASHEW | F27: MANH TUAN | G27: WW320 | H27: 2025 | I27: FLEXIPACKS | J27: 3.27 | K27: =M27/N27 -> 0.074909091 | L27: =K27+J27 -> 3.3449091 | M27: 4120 | N27: =Q27*55000 -> 55000 | O27: =N27*0.4536 -> 24948 | P27: 40 | Q27: 1 | R27: MSBU4590335 | T27: MEDUHQ437756 | U27: EBKG13296549 | V27: 25258-IT25154192 | W27: HD29612-2 | X27: =IFERROR(INDEX('GİRİŞ ANALİZİ'!$D:$D, MATCH($W27,'GİRİŞ ANALİZİ'!$B:$B, 0)),"Bulunamadı") -> 28 | Y27: 45844 | Z27: 45898 | AA27: =Z27-Y27 -> 54 | AB27: İçeri Çekildi
A28: 45803 | B28: 625591 | C28: H5130003 | D28: =IF(C28="H5130003","HW.CASHEW NUT W320____________( 22.68 KG )",IF(C28="H5130001","HW.CASHEW NUT W240____________( 22.68 KG )",IF(C28="H5130164","HW.CASHEW NUT W180____________( 22.68 KG )",""))) -> HW.CASHEW NUT W320____________( 22.68 KG ) | E28: HD CASHEW | F28: LIEN VIET | G28: WW320 | H28: 2025 | I28: FLEXIPACKS | J28: 3.25 | K28: =M28/N28 -> 0.074909091 | L28: =K28+J28 -> 3.3249091 | M28: 4120 | N28: =Q28*55000 -> 55000 | O28: =N28*0.4536 -> 24948 | P28: 40 | Q28: 1 | R28: FSCU4163089 | T28: MEDUHQ493825 | U28: EBKG13395422 | V28: 25261-IT25154191 | W28: HD29412-1 | X28: =IFERROR(INDEX('GİRİŞ ANALİZİ'!$D:$D, MATCH($W28,'GİRİŞ ANALİZİ'!$B:$B, 0)),"Bulunamadı") -> 27 | Y28: 45844 | Z28: 45898 | AA28: =Z28-Y28 -> 54 | AB28: İçeri Çekildi
A29: 45803 | B29: 625591 | C29: H5130003 | D29: =IF(C29="H5130003","HW.CASHEW NUT W320____________( 22.68 KG )",IF(C29="H5130001","HW.CASHEW NUT W240____________( 22.68 KG )",IF(C29="H5130164","HW.CASHEW NUT W180____________( 22.68 KG )",""))) -> HW.CASHEW NUT W320____________( 22.68 KG ) | E29: HD CASHEW | F29: LIEN VIET | G29: WW320 | H29: 2025 | I29: FLEXIPACKS | J29: 3.25 | K29: =M29/N29 -> 0.072727273 | L29: =K29+J29 -> 3.3227273 | M29: 4000 | N29: =Q29*55000 -> 55000 | O29: =N29*0.4536 -> 24948 | P29: 40 | Q29: 1 | R29: MSBU4022649 | T29: MEDUHQ575332 | U29: EBKG13557543 | V29: 25261-IT25154191 | W29: HD29412-2 | X29: =IFERROR(INDEX('GİRİŞ ANALİZİ'!$D:$D, MATCH($W29,'GİRİŞ ANALİZİ'!$B:$B, 0)),"Bulunamadı") -> 30 | Y29: 45859 | Z29: 45911 | AA29: =Z29-Y29 -> 52 | AB29: İçeri Çekildi
A30: 45803 | B30: 625591 | C30: H5130003 | D30: =IF(C30="H5130003","HW.CASHEW NUT W320____________( 22.68 KG )",IF(C30="H5130001","HW.CASHEW NUT W240____________( 22.68 KG )",IF(C30="H5130164","HW.CASHEW NUT W180____________( 22.68 KG )",""))) -> HW.CASHEW NUT W320____________( 22.68 KG ) | E30: HD CASHEW | F30: LIEN VIET | G30: WW320 | H30: 2025 | I30: FLEXIPACKS | J30: 3.25 | K30: =M30/N30 -> 0.072727273 | L30: =K30+J30 -> 3.3227273 | M30: 4000 | N30: =Q30*55000 -> 55000 | O30: =N30*0.4536 -> 24948 | P30: 40 | Q30: 1 | R30: TCKU4301533 | T30: MEDUHQ575332 | U30: EBKG13557543 | V30: 25261-IT25154191 | W30: HD29412-3 | X30: =IFERROR(INDEX('GİRİŞ ANALİZİ'!$D:$D, MATCH($W30,'GİRİŞ ANALİZİ'!$B:$B, 0)),"Bulunamadı") -> 29 | Y30: 45859 | Z30: 45911 | AA30: =Z30-Y30 -> 52 | AB30: İçeri Çekildi
A31: 45803 | B31: 625591 | C31: H5130003 | D31: =IF(C31="H5130003","HW.CASHEW NUT W320____________( 22.68 KG )",IF(C31="H5130001","HW.CASHEW NUT W240____________( 22.68 KG )",IF(C31="H5130164","HW.CASHEW NUT W180____________( 22.68 KG )",""))) -> HW.CASHEW NUT W320____________( 22.68 KG ) | E31: HD CASHEW | F31: LIEN VIET | G31: WW320 | H31: 2025 | I31: FLEXIPACKS | J31: 3.25 | K31: =M31/N31 -> 0.072727273 | L31: =K31+J31 -> 3.3227273 | M31: 4000 | N31: =Q31*55000 -> 55000 | O31: =N31*0.4536 -> 24948 | P31: 40 | Q31: 1 | R31: TXGU7262063 | S31: AN00039126 | T31: MEDUHQ721324 | U31: EBKG13861396 | V31: 25261-IT25154191 | W31: HD29412-4 | X31: =IFERROR(INDEX('GİRİŞ ANALİZİ'!$D:$D, MATCH($W31,'GİRİŞ ANALİZİ'!$B:$B, 0)),"Bulunamadı") -> 32 | Y31: 45888 | Z31: 45934 | AA31: =Z31-Y31 -> 46 | AB31: İçeri Çekildi
A32: 45803 | B32: 625591 | C32: H5130003 | D32: =IF(C32="H5130003","HW.CASHEW NUT W320____________( 22.68 KG )",IF(C32="H5130001","HW.CASHEW NUT W240____________( 22.68 KG )",IF(C32="H5130164","HW.CASHEW NUT W180____________( 22.68 KG )",""))) -> HW.CASHEW NUT W320____________( 22.68 KG ) | E32: HD CASHEW | F32: LIEN VIET | G32: WW320 | H32: 2025 | I32: FLEXIPACKS | J32: 3.25 | K32: =M32/N32 -> 0.072727273 | L32: =K32+J32 -> 3.3227273 | M32: 4000 | N32: =Q32*55000 -> 55000 | O32: =N32*0.4536 -> 24948 | P32: 40 | Q32: 1 | R32: GAOU7622115 | S32: AN00039126 | T32: MEDUHQ721324 | U32: EBKG13861396 | V32: 25261-IT25154191 | W32: HD29412-5 | X32: =IFERROR(INDEX('GİRİŞ ANALİZİ'!$D:$D, MATCH($W32,'GİRİŞ ANALİZİ'!$B:$B, 0)),"Bulunamadı") -> 31 | Y32: 45888 | Z32: 45934 | AA32: =Z32-Y32 -> 46 | AB32: İçeri Çekildi
A33: 45803 | B33: 625591 | C33: H5130003 | D33: =IF(C33="H5130003","HW.CASHEW NUT W320____________( 22.68 KG )",IF(C33="H5130001","HW.CASHEW NUT W240____________( 22.68 KG )",IF(C33="H5130164","HW.CASHEW NUT W180____________( 22.68 KG )",""))) -> HW.CASHEW NUT W320____________( 22.68 KG ) | E33: HD CASHEW | F33: LIEN VIET | G33: WW320 | H33: 2025 | I33: FLEXIPACKS | J33: 3.25 | K33: =M33/N33 -> 0.072727273 | L33: =K33+J33 -> 3.3227273 | M33: 4000 | N33: =Q33*55000 -> 55000 | O33: =N33*0.4536 -> 24948 | P33: 40 | Q33: 1 | R33: MSDU7330895 | S33: AN0003984 | T33: MEDUHQ769349 | U33: EBKG13940113 | V33: 25261-IT25154191 | W33: HD29412-6 | X33: =IFERROR(INDEX('GİRİŞ ANALİZİ'!$D:$D, MATCH($W33,'GİRİŞ ANALİZİ'!$B:$B, 0)),"Bulunamadı") -> 34 | Y33: 45894 | Z33: 45942 | AA33: =Z33-Y33 -> 48 | AB33: İçeri Çekildi
A34: 45862 | B34: 632900 | C34: H5130003 | D34: =IF(C34="H5130003","HW.CASHEW NUT W320____________( 22.68 KG )",IF(C34="H5130001","HW.CASHEW NUT W240____________( 22.68 KG )",IF(C34="H5130164","HW.CASHEW NUT W180____________( 22.68 KG )",""))) -> HW.CASHEW NUT W320____________( 22.68 KG ) | E34: HD CASHEW | F34: LIEN VIET | G34: WW320 | H34: 2025 | I34: FLEXIPACKS | J34: 3.16 | K34: =M34/N34 -> 0.072727273 | L34: =K34+J34 -> 3.2327273 | M34: 4000 | N34: =Q34*55000 -> 55000 | O34: =N34*0.4536 -> 24948 | P34: 40 | Q34: 1 | R34: MSMU4735690 | S34: AN00039845 | T34: MEDUHQ768986 | U34: EBKG13939828 | V34: 25286-IT25154209 | W34: HD41312 | X34: =IFERROR(INDEX('GİRİŞ ANALİZİ'!$D:$D, MATCH($W34,'GİRİŞ ANALİZİ'!$B:$B, 0)),"Bulunamadı") -> Bulunamadı | Y34: 45894 | Z34: 45942 | AA34: =Z34-Y34 -> 48 | AB34: Antrepoda
A35: 45803 | B35: 625591 | C35: H5130003 | D35: =IF(C35="H5130003","HW.CASHEW NUT W320____________( 22.68 KG )",IF(C35="H5130001","HW.CASHEW NUT W240____________( 22.68 KG )",IF(C35="H5130164","HW.CASHEW NUT W180____________( 22.68 KG )",""))) -> HW.CASHEW NUT W320____________( 22.68 KG ) | E35: HD CASHEW | F35: LIEN VIET | G35: WW320 | H35: 2025 | I35: FLEXIPACKS | J35: 3.25 | K35: =M35/N35 -> 0.072727273 | L35: =K35+J35 -> 3.3227273 | M35: 4000 | N35: =Q35*55000 -> 55000 | O35: =N35*0.4536 -> 24948 | P35: 40 | Q35: 1 | R35: MSDU6853314 | T35: MEDUHQ985556 | U35: EBKG14296265 | V35: 25261-IT25154191 | W35: HD29412-7 | X35: =IFERROR(INDEX('GİRİŞ ANALİZİ'!$D:$D, MATCH($W35,'GİRİŞ ANALİZİ'!$B:$B, 0)),"Bulunamadı") -> Bulunamadı | Y35: 45935 | Z35: 45983 | AA35: =Z35-Y35 -> 48 | AB35: Limanda
A36: 45803 | B36: 625591 | C36: H5130003 | D36: =IF(C36="H5130003","HW.CASHEW NUT W320____________( 22.68 KG )",IF(C36="H5130001","HW.CASHEW NUT W240____________( 22.68 KG )",IF(C36="H5130164","HW.CASHEW NUT W180____________( 22.68 KG )",""))) -> HW.CASHEW NUT W320____________( 22.68 KG ) | E36: HD CASHEW | F36: LIEN VIET | G36: WW320 | H36: 2025 | I36: FLEXIPACKS | J36: 3.25 | K36: =M36/N36 -> 0.072727273 | L36: =K36+J36 -> 3.3227273 | M36: 4000 | N36: =Q36*55000 -> 55000 | O36: =N36*0.4536 -> 24948 | P36: 40 | Q36: 1 | R36: MSDU8079953 | T36: MEDUHQ985556 | U36: EBKG14296265 | V36: 25261-IT25154191 | W36: HD29412-8 | X36: =IFERROR(INDEX('GİRİŞ ANALİZİ'!$D:$D, MATCH($W36,'GİRİŞ ANALİZİ'!$B:$B, 0)),"Bulunamadı") -> Bulunamadı | Y36: 45935 | Z36: 45983 | AA36: =Z36-Y36 -> 48 | AB36: Limanda
A37: 45803 | B37: 625591 | C37: H5130003 | D37: =IF(C37="H5130003","HW.CASHEW NUT W320____________( 22.68 KG )",IF(C37="H5130001","HW.CASHEW NUT W240____________( 22.68 KG )",IF(C37="H5130164","HW.CASHEW NUT W180____________( 22.68 KG )",""))) -> HW.CASHEW NUT W320____________( 22.68 KG ) | E37: HD CASHEW | F37: LIEN VIET | G37: WW320 | H37: 2025 | I37: FLEXIPACKS | J37: 3.25 | K37: =M37/N37 -> 0.072727273 | L37: =K37+J37 -> 3.3227273 | M37: 4000 | N37: =Q37*55000 -> 55000 | O37: =N37*0.4536 -> 24948 | P37: 40 | Q37: 1 | R37: MSDU6116169 | T37: MEDUHQ985556 | U37: EBKG14340236 | V37: 25261-IT25154191 | W37: HD29412-9 | X37: =IFERROR(INDEX('GİRİŞ ANALİZİ'!$D:$D, MATCH($W37,'GİRİŞ ANALİZİ'!$B:$B, 0)),"Bulunamadı") -> Bulunamadı | Y37: 45935 | Z37: 45983 | AA37: =Z37-Y37 -> 48 | AB37: Limanda
A38: 45902 | B38: 637501 | C38: H5130003 | D38: =IF(C38="H5130003","HW.CASHEW NUT W320____________( 22.68 KG )",IF(C38="H5130001","HW.CASHEW NUT W240____________( 22.68 KG )",IF(C38="H5130164","HW.CASHEW NUT W180____________( 22.68 KG )",""))) -> HW.CASHEW NUT W320____________( 22.68 KG ) | E38: HD CASHEW | F38: NGAN NGOC | G38: WW320 | H38: 2025 | I38: FLEXIPACKS | J38: 3.12 | K38: =M38/55000 -> 0.072727273 | L38: =J38+K38 -> 3.1927273 | M38: 4000 | N38: =Q38*55000 -> 55000 | O38: =N38*0.4536 -> 24948 | P38: 40 | Q38: 1 | R38: MSDU4075939 | S38: AN00040536 | T38: MEDUHQ833079 | U38: EBKG14066450 | V38: 26001-IT26154001 | W38: HD46212-1 | X38: =IFERROR(INDEX('GİRİŞ ANALİZİ'!$D:$D, MATCH($W38,'GİRİŞ ANALİZİ'!$B:$B, 0)),"Bulunamadı") -> 35 | Y38: 45908 | Z38: 45954 | AA38: =Z38-Y38 -> 46 | AB38: İçeri Çekildi
A39: 45902 | B39: 637501 | C39: H5130003 | D39: =IF(C39="H5130003","HW.CASHEW NUT W320____________( 22.68 KG )",IF(C39="H5130001","HW.CASHEW NUT W240____________( 22.68 KG )",IF(C39="H5130164","HW.CASHEW NUT W180____________( 22.68 KG )",""))) -> HW.CASHEW NUT W320____________( 22.68 KG ) | E39: HD CASHEW | F39: NGAN NGOC | G39: WW320 | H39: 2025 | I39: FLEXIPACKS | J39: 3.12 | K39: =M39/55000 -> 0.072727273 | L39: =J39+K39 -> 3.1927273 | M39: 4000 | N39: =Q39*55000 -> 55000 | O39: =N39*0.4536 -> 24948 | P39: 40 | Q39: 1 | R39: MSBU4597622 | S39: AN00043760 | T39: MEDUHQ845693 | U39: EBKG14066518 | V39: 26001-IT26154001 | W39: HD46212-2 | X39: =IFERROR(INDEX('GİRİŞ ANALİZİ'!$D:$D, MATCH($W39,'GİRİŞ ANALİZİ'!$B:$B, 0)),"Bulunamadı") -> Bulunamadı | Y39: 45916 | Z39: 45975 | AA39: =+Z39-Y39 -> 59 | AB39: Antrepoda
A40: 45902 | B40: 637503 | C40: H5130003 | D40: =IF(C40="H5130003","HW.CASHEW NUT W320____________( 22.68 KG )",IF(C40="H5130001","HW.CASHEW NUT W240____________( 22.68 KG )",IF(C40="H5130164","HW.CASHEW NUT W180____________( 22.68 KG )",""))) -> HW.CASHEW NUT W320____________( 22.68 KG ) | E40: HD CASHEW | F40: MANH TUAN | G40: WW320 | H40: 2025 | I40: FLEXIPACKS | J40: 3.15 | K40: =M40/55000 -> 0.072727273 | L40: =J40+K40 -> 3.2227273 | M40: 4000 | N40: =Q40*55000 -> 55000 | O40: =N40*0.4536 -> 24948 | P40: 40 | Q40: 1 | R40: MSDU4045390 | T40: MEDUHQ929687 | U40: EBKG14241605 | V40: 26002-IT26154002 | W40: HD46312-1 | X40: =IFERROR(INDEX('GİRİŞ ANALİZİ'!$D:$D, MATCH($W40,'GİRİŞ ANALİZİ'!$B:$B, 0)),"Bulunamadı") -> Bulunamadı | Y40: 45935 | Z40: 45984 | AA40: =+Z40-Y40 -> 49 | AB40: Limanda
...

Sheet ANTREPO
A1: Satın Alma Bağlantısı | B1: Firma Adı | C1: Stok Kodu | D1: Stok Adı | E1: Kg | F1: Konteyner No | G1: Tır No | H1: Parti No | I1: Antrepo No | J1: B/L No | K1: Ref. No | L1: Contract No
A2: =IFERROR(HYPERLINK("#"&ADDRESS(MATCH($F2,'SATIN ALMA'!$R:$R,0),COLUMN('SATIN ALMA'!$R:$R),1,1,"SATIN ALMA"),"Git →"),"Bulunamadı") -> Git → | B2: =IFERROR(INDEX('SATIN ALMA'!$F:$F, MATCH($F2, 'SATIN ALMA'!$R:$R, 0)),"Bulunamadı") -> LIEN VIET | C2: =IFERROR(INDEX('SATIN ALMA'!$C:$C, MATCH($F2, 'SATIN ALMA'!$R:$R, 0)),"Bulunamadı" ) -> H5130003 | D2: =IFERROR(INDEX('SATIN ALMA'!$D:$D, MATCH($F2, 'SATIN ALMA'!$R:$R, 0)),"Bulunamadı" ) -> HW.CASHEW NUT W320____________( 22.68 KG ) | E2: =IFERROR(INDEX('SATIN ALMA'!$O:$O, MATCH($F2, 'SATIN ALMA'!$R:$R, 0)),"Bulunamadı" ) -> 24948 | F2: MSMU4735690 | G2: =IFERROR(INDEX('GİRİŞ ANALİZİ'!$D:$D, MATCH($F2, 'GİRİŞ ANALİZİ'!$C:$C, 0)),"Bulunamadı" ) -> Bulunamadı | H2: =IFERROR(INDEX('GİRİŞ ANALİZİ'!$E:$E, MATCH($F2, 'GİRİŞ ANALİZİ'!$C:$C, 0)),"Bulunamadı" ) -> Bulunamadı | I2: =IFERROR(INDEX('SATIN ALMA'!$S:$S, MATCH(F2, 'SATIN ALMA'!$R:$R, 0)),"Bulunamadı" ) -> AN00039845 | J2: =IFERROR(INDEX('SATIN ALMA'!$T:$T, MATCH($F2, 'SATIN ALMA'!$R:$R, 0)),"Bulunamadı") -> MEDUHQ768986 | K2: =IFERROR(INDEX('SATIN ALMA'!$V:$V, MATCH($F2, 'SATIN ALMA'!$R:$R, 0)),"Bulunamadı" ) -> 25286-IT25154209 | L2: =IFERROR( INDEX('SATIN ALMA'!$W:$W, MATCH($F2, 'SATIN ALMA'!$R:$R, 0)), "Bulunamadı" ) -> HD41312
A3: =IFERROR(HYPERLINK("#"&ADDRESS(MATCH($F3,'SATIN ALMA'!$R:$R,0),COLUMN('SATIN ALMA'!$R:$R),1,1,"SATIN ALMA"),"Git →"),"Bulunamadı") -> Git → | B3: =IFERROR(INDEX('SATIN ALMA'!$F:$F, MATCH($F3, 'SATIN ALMA'!$R:$R, 0)),"Bulunamadı") -> MANH TUAN | C3: =IFERROR(INDEX('SATIN ALMA'!$C:$C, MATCH($F3, 'SATIN ALMA'!$R:$R, 0)),"Bulunamadı" ) -> H5130003 | D3: =IFERROR(INDEX('SATIN ALMA'!$D:$D, MATCH($F3, 'SATIN ALMA'!$R:$R, 0)),"Bulunamadı" ) -> HW.CASHEW NUT W320____________( 22.68 KG ) | E3: =IFERROR(INDEX('SATIN ALMA'!$O:$O, MATCH($F3, 'SATIN ALMA'!$R:$R, 0)),"Bulunamadı" ) -> 24948 | F3: MSDU4135684 | G3: =IFERROR(INDEX('GİRİŞ ANALİZİ'!$D:$D, MATCH($F3, 'GİRİŞ ANALİZİ'!$C:$C, 0)),"Bulunamadı" ) -> Bulunamadı | H3: =IFERROR(INDEX('GİRİŞ ANALİZİ'!$E:$E, MATCH($F3, 'GİRİŞ ANALİZİ'!$C:$C, 0)),"Bulunamadı" ) -> Bulunamadı | I3: =IFERROR(INDEX('SATIN ALMA'!$S:$S, MATCH(F3, 'SATIN ALMA'!$R:$R, 0)),"Bulunamadı" ) -> AN00043225 | J3: =IFERROR(INDEX('SATIN ALMA'!$T:$T, MATCH($F3, 'SATIN ALMA'!$R:$R, 0)),"Bulunamadı") -> MEDUHQ815092 | K3: =IFERROR(INDEX('SATIN ALMA'!$V:$V, MATCH($F3, 'SATIN ALMA'!$R:$R, 0)),"Bulunamadı" ) -> 26008-IT26154012 | L3: =IFERROR( INDEX('SATIN ALMA'!$W:$W, MATCH($F3, 'SATIN ALMA'!$R:$R, 0)), "Bulunamadı" ) -> HD47612-2
A4: =IFERROR(HYPERLINK("#"&ADDRESS(MATCH($F4,'SATIN ALMA'!$R:$R,0),COLUMN('SATIN ALMA'!$R:$R),1,1,"SATIN ALMA"),"Git →"),"Bulunamadı") -> Git → | B4: =IFERROR(INDEX('SATIN ALMA'!$F:$F, MATCH($F4, 'SATIN ALMA'!$R:$R, 0)),"Bulunamadı") -> TRU LANH | C4: =IFERROR(INDEX('SATIN ALMA'!$C:$C, MATCH($F4, 'SATIN ALMA'!$R:$R, 0)),"Bulunamadı" ) -> H5130003 | D4: =IFERROR(INDEX('SATIN ALMA'!$D:$D, MATCH($F4, 'SATIN ALMA'!$R:$R, 0)),"Bulunamadı" ) -> HW.CASHEW NUT W320____________( 22.68 KG ) | E4: =IFERROR(INDEX('SATIN ALMA'!$O:$O, MATCH($F4, 'SATIN ALMA'!$R:$R, 0)),"Bulunamadı" ) -> 24948 | F4: MSDU4174741 | G4: =IFERROR(INDEX('GİRİŞ ANALİZİ'!$D:$D, MATCH($F4, 'GİRİŞ ANALİZİ'!$C:$C, 0)),"Bulunamadı" ) -> Bulunamadı | H4: =IFERROR(INDEX('GİRİŞ ANALİZİ'!$E:$E, MATCH($F4, 'GİRİŞ ANALİZİ'!$C:$C, 0)),"Bulunamadı" ) -> Bulunamadı | I4: =IFERROR(INDEX('SATIN ALMA'!$S:$S, MATCH(F4, 'SATIN ALMA'!$R:$R, 0)),"Bulunamadı" ) -> AN00043228 | J4: =IFERROR(INDEX('SATIN ALMA'!$T:$T, MATCH($F4, 'SATIN ALMA'!$R:$R, 0)),"Bulunamadı") -> MEDUHQ862177 | K4: =IFERROR(INDEX('SATIN ALMA'!$V:$V, MATCH($F4, 'SATIN ALMA'!$R:$R, 0)),"Bulunamadı" ) -> 26006-IT26154006 | L4: =IFERROR( INDEX('SATIN ALMA'!$W:$W, MATCH($F4, 'SATIN ALMA'!$R:$R, 0)), "Bulunamadı" ) -> HD47712-2
A5: =IFERROR(HYPERLINK("#"&ADDRESS(MATCH($F5,'SATIN ALMA'!$R:$R,0),COLUMN('SATIN ALMA'!$R:$R),1,1,"SATIN ALMA"),"Git →"),"Bulunamadı") -> Git → | B5: =IFERROR(INDEX('SATIN ALMA'!$F:$F, MATCH($F5, 'SATIN ALMA'!$R:$R, 0)),"Bulunamadı") -> TRU LANH | C5: =IFERROR(INDEX('SATIN ALMA'!$C:$C, MATCH($F5, 'SATIN ALMA'!$R:$R, 0)),"Bulunamadı" ) -> H5130003 | D5: =IFERROR(INDEX('SATIN ALMA'!$D:$D, MATCH($F5, 'SATIN ALMA'!$R:$R, 0)),"Bulunamadı" ) -> HW.CASHEW NUT W320____________( 22.68 KG ) | E5: =IFERROR(INDEX('SATIN ALMA'!$O:$O, MATCH($F5, 'SATIN ALMA'!$R:$R, 0)),"Bulunamadı" ) -> 24948 | F5: MSBU4024322 | G5: =IFERROR(INDEX('GİRİŞ ANALİZİ'!$D:$D, MATCH($F5, 'GİRİŞ ANALİZİ'!$C:$C, 0)),"Bulunamadı" ) -> Bulunamadı | H5: =IFERROR(INDEX('GİRİŞ ANALİZİ'!$E:$E, MATCH($F5, 'GİRİŞ ANALİZİ'!$C:$C, 0)),"Bulunamadı" ) -> Bulunamadı | I5: =IFERROR(INDEX('SATIN ALMA'!$S:$S, MATCH(F5, 'SATIN ALMA'!$R:$R, 0)),"Bulunamadı" ) -> AN00043227 | J5: =IFERROR(INDEX('SATIN ALMA'!$T:$T, MATCH($F5, 'SATIN ALMA'!$R:$R, 0)),"Bulunamadı") -> MEDUHQ862268 | K5: =IFERROR(INDEX('SATIN ALMA'!$V:$V, MATCH($F5, 'SATIN ALMA'!$R:$R, 0)),"Bulunamadı" ) -> 26006-IT26154006 | L5: =IFERROR( INDEX('SATIN ALMA'!$W:$W, MATCH($F5, 'SATIN ALMA'!$R:$R, 0)), "Bulunamadı" ) -> HD47712-1
A6: =IFERROR(HYPERLINK("#"&ADDRESS(MATCH($F6,'SATIN ALMA'!$R:$R,0),COLUMN('SATIN ALMA'!$R:$R),1,1,"SATIN ALMA"),"Git →"),"Bulunamadı") -> Git → | B6: =IFERROR(INDEX('SATIN ALMA'!$F:$F, MATCH($F6, 'SATIN ALMA'!$R:$R, 0)),"Bulunamadı") -> LIEN VIET | C6: =IFERROR(INDEX('SATIN ALMA'!$C:$C, MATCH($F6, 'SATIN ALMA'!$R:$R, 0)),"Bulunamadı" ) -> H5130164 | D6: =IFERROR(INDEX('SATIN ALMA'!$D:$D, MATCH($F6, 'SATIN ALMA'!$R:$R, 0)),"Bulunamadı" ) -> HW.CASHEW NUT W180____________( 22.68 KG ) | E6: =IFERROR(INDEX('SATIN ALMA'!$O:$O, MATCH($F6, 'SATIN ALMA'!$R:$R, 0)),"Bulunamadı" ) -> 24948 | F6: TRHU7347860 | G6: =IFERROR(INDEX('GİRİŞ ANALİZİ'!$D:$D, MATCH($F6, 'GİRİŞ ANALİZİ'!$C:$C, 0)),"Bulunamadı" ) -> Bulunamadı | H6: =IFERROR(INDEX('GİRİŞ ANALİZİ'!$E:$E, MATCH($F6, 'GİRİŞ ANALİZİ'!$C:$C, 0)),"Bulunamadı" ) -> Bulunamadı | I6: =IFERROR(INDEX('SATIN ALMA'!$S:$S, MATCH(F6, 'SATIN ALMA'!$R:$R, 0)),"Bulunamadı" ) -> AN00043756 | J6: =IFERROR(INDEX('SATIN ALMA'!$T:$T, MATCH($F6, 'SATIN ALMA'!$R:$R, 0)),"Bulunamadı") -> MEDUHQ854240 | K6: =IFERROR(INDEX('SATIN ALMA'!$V:$V, MATCH($F6, 'SATIN ALMA'!$R:$R, 0)),"Bulunamadı" ) -> 26010-IT25154014 | L6: =IFERROR( INDEX('SATIN ALMA'!$W:$W, MATCH($F6, 'SATIN ALMA'!$R:$R, 0)), "Bulunamadı" ) -> HD48112
A7: =IFERROR(HYPERLINK("#"&ADDRESS(MATCH($F7,'SATIN ALMA'!$R:$R,0),COLUMN('SATIN ALMA'!$R:$R),1,1,"SATIN ALMA"),"Git →"),"Bulunamadı") -> Git → | B7: =IFERROR(INDEX('SATIN ALMA'!$F:$F, MATCH($F7, 'SATIN ALMA'!$R:$R, 0)),"Bulunamadı") -> LIEN VIET | C7: =IFERROR(INDEX('SATIN ALMA'!$C:$C, MATCH($F7, 'SATIN ALMA'!$R:$R, 0)),"Bulunamadı" ) -> H5130003 | D7: =IFERROR(INDEX('SATIN ALMA'!$D:$D, MATCH($F7, 'SATIN ALMA'!$R:$R, 0)),"Bulunamadı" ) -> HW.CASHEW NUT W320____________( 22.68 KG ) | E7: =IFERROR(INDEX('SATIN ALMA'!$O:$O, MATCH($F7, 'SATIN ALMA'!$R:$R, 0)),"Bulunamadı" ) -> 24948 | F7: MSMU8467868 | G7: =IFERROR(INDEX('GİRİŞ ANALİZİ'!$D:$D, MATCH($F7, 'GİRİŞ ANALİZİ'!$C:$C, 0)),"Bulunamadı" ) -> Bulunamadı | H7: =IFERROR(INDEX('GİRİŞ ANALİZİ'!$E:$E, MATCH($F7, 'GİRİŞ ANALİZİ'!$C:$C, 0)),"Bulunamadı" ) -> Bulunamadı | I7: =IFERROR(INDEX('SATIN ALMA'!$S:$S, MATCH(F7, 'SATIN ALMA'!$R:$R, 0)),"Bulunamadı" ) -> AN00043759 | J7: =IFERROR(INDEX('SATIN ALMA'!$T:$T, MATCH($F7, 'SATIN ALMA'!$R:$R, 0)),"Bulunamadı") -> MEDUHQ837781 | K7: =IFERROR(INDEX('SATIN ALMA'!$V:$V, MATCH($F7, 'SATIN ALMA'!$R:$R, 0)),"Bulunamadı" ) -> 26010-IT26154014 | L7: =IFERROR( INDEX('SATIN ALMA'!$W:$W, MATCH($F7, 'SATIN ALMA'!$R:$R, 0)), "Bulunamadı" ) -> HD48012-1
A8: =IFERROR(HYPERLINK("#"&ADDRESS(MATCH($F8,'SATIN ALMA'!$R:$R,0),COLUMN('SATIN ALMA'!$R:$R),1,1,"SATIN ALMA"),"Git →"),"Bulunamadı") -> Git → | B8: =IFERROR(INDEX('SATIN ALMA'!$F:$F, MATCH($F8, 'SATIN ALMA'!$R:$R, 0)),"Bulunamadı") -> LIEN VIET | C8: =IFERROR(INDEX('SATIN ALMA'!$C:$C, MATCH($F8, 'SATIN ALMA'!$R:$R, 0)),"Bulunamadı" ) -> H5130003 | D8: =IFERROR(INDEX('SATIN ALMA'!$D:$D, MATCH($F8, 'SATIN ALMA'!$R:$R, 0)),"Bulunamadı" ) -> HW.CASHEW NUT W320____________( 22.68 KG ) | E8: =IFERROR(INDEX('SATIN ALMA'!$O:$O, MATCH($F8, 'SATIN ALMA'!$R:$R, 0)),"Bulunamadı" ) -> 24948 | F8: MSMU6646910 | G8: =IFERROR(INDEX('GİRİŞ ANALİZİ'!$D:$D, MATCH($F8, 'GİRİŞ ANALİZİ'!$C:$C, 0)),"Bulunamadı" ) -> Bulunamadı | H8: =IFERROR(INDEX('GİRİŞ ANALİZİ'!$E:$E, MATCH($F8, 'GİRİŞ ANALİZİ'!$C:$C, 0)),"Bulunamadı" ) -> Bulunamadı | I8: =IFERROR(INDEX('SATIN ALMA'!$S:$S, MATCH(F8, 'SATIN ALMA'!$R:$R, 0)),"Bulunamadı" ) -> AN00043759 | J8: =IFERROR(INDEX('SATIN ALMA'!$T:$T, MATCH($F8, 'SATIN ALMA'!$R:$R, 0)),"Bulunamadı") -> MEDUHQ837781 | K8: =IFERROR(INDEX('SATIN ALMA'!$V:$V, MATCH($F8, 'SATIN ALMA'!$R:$R, 0)),"Bulunamadı" ) -> 26010-IT26154014 | L8: =IFERROR( INDEX('SATIN ALMA'!$W:$W, MATCH($F8, 'SATIN ALMA'!$R:$R, 0)), "Bulunamadı" ) -> HD48012-2
A9: =IFERROR(HYPERLINK("#"&ADDRESS(MATCH($F9,'SATIN ALMA'!$R:$R,0),COLUMN('SATIN ALMA'!$R:$R),1,1,"SATIN ALMA"),"Git →"),"Bulunamadı") -> Git → | B9: =IFERROR(INDEX('SATIN ALMA'!$F:$F, MATCH($F9, 'SATIN ALMA'!$R:$R, 0)),"Bulunamadı") -> NGAN NGOC | C9: =IFERROR(INDEX('SATIN ALMA'!$C:$C, MATCH($F9, 'SATIN ALMA'!$R:$R, 0)),"Bulunamadı" ) -> H5130003 | D9: =IFERROR(INDEX('SATIN ALMA'!$D:$D, MATCH($F9, 'SATIN ALMA'!$R:$R, 0)),"Bulunamadı" ) -> HW.CASHEW NUT W320____________( 22.68 KG ) | E9: =IFERROR(INDEX('SATIN ALMA'!$O:$O, MATCH($F9, 'SATIN ALMA'!$R:$R, 0)),"Bulunamadı" ) -> 24948 | F9: MSBU4587120 | G9: =IFERROR(INDEX('GİRİŞ ANALİZİ'!$D:$D, MATCH($F9, 'GİRİŞ ANALİZİ'!$C:$C, 0)),"Bulunamadı" ) -> Bulunamadı | H9: =IFERROR(INDEX('GİRİŞ ANALİZİ'!$E:$E, MATCH($F9, 'GİRİŞ ANALİZİ'!$C:$C, 0)),"Bulunamadı" ) -> Bulunamadı | I9: =IFERROR(INDEX('SATIN ALMA'!$S:$S, MATCH(F9, 'SATIN ALMA'!$R:$R, 0)),"Bulunamadı" ) -> AN00043755 | J9: =IFERROR(INDEX('SATIN ALMA'!$T:$T, MATCH($F9, 'SATIN ALMA'!$R:$R, 0)),"Bulunamadı") -> MEDUHQ845800 | K9: =IFERROR(INDEX('SATIN ALMA'!$V:$V, MATCH($F9, 'SATIN ALMA'!$R:$R, 0)),"Bulunamadı" ) -> 26009-IT26154013 | L9: =IFERROR( INDEX('SATIN ALMA'!$W:$W, MATCH($F9, 'SATIN ALMA'!$R:$R, 0)), "Bulunamadı" ) -> HD47812
A10: =IFERROR(HYPERLINK("#"&ADDRESS(MATCH($F10,'SATIN ALMA'!$R:$R,0),COLUMN('SATIN ALMA'!$R:$R),1,1,"SATIN ALMA"),"Git →"),"Bulunamadı") -> Git → | B10: =IFERROR(INDEX('SATIN ALMA'!$F:$F, MATCH($F10, 'SATIN ALMA'!$R:$R, 0)),"Bulunamadı") -> NGAN NGOC | C10: =IFERROR(INDEX('SATIN ALMA'!$C:$C, MATCH($F10, 'SATIN ALMA'!$R:$R, 0)),"Bulunamadı" ) -> H5130003 | D10: =IFERROR(INDEX('SATIN ALMA'!$D:$D, MATCH($F10, 'SATIN ALMA'!$R:$R, 0)),"Bulunamadı" ) -> HW.CASHEW NUT W320____________( 22.68 KG ) | E10: =IFERROR(INDEX('SATIN ALMA'!$O:$O, MATCH($F10, 'SATIN ALMA'!$R:$R, 0)),"Bulunamadı" ) -> 24948 | F10: MSBU4597622 | G10: =IFERROR(INDEX('GİRİŞ ANALİZİ'!$D:$D, MATCH($F10, 'GİRİŞ ANALİZİ'!$C:$C, 0)),"Bulunamadı" ) -> Bulunamadı | H10: =IFERROR(INDEX('GİRİŞ ANALİZİ'!$E:$E, MATCH($F10, 'GİRİŞ ANALİZİ'!$C:$C, 0)),"Bulunamadı" ) -> Bulunamadı | I10: =IFERROR(INDEX('SATIN ALMA'!$S:$S, MATCH(F10, 'SATIN ALMA'!$R:$R, 0)),"Bulunamadı" ) -> AN00043760 | J10: =IFERROR(INDEX('SATIN ALMA'!$T:$T, MATCH($F10, 'SATIN ALMA'!$R:$R, 0)),"Bulunamadı") -> MEDUHQ845693 | K10: =IFERROR(INDEX('SATIN ALMA'!$V:$V, MATCH($F10, 'SATIN ALMA'!$R:$R, 0)),"Bulunamadı" ) -> 26001-IT26154001 | L10: =IFERROR( INDEX('SATIN ALMA'!$W:$W, MATCH($F10, 'SATIN ALMA'!$R:$R, 0)), "Bulunamadı" ) -> HD46212-2
A11: =IFERROR(HYPERLINK("#"&ADDRESS(MATCH($F11,'SATIN ALMA'!$R:$R,0),COLUMN('SATIN ALMA'!$R:$R),1,1,"SATIN ALMA"),"Git →"),"Bulunamadı") -> Bulunamadı | B11: =IFERROR(INDEX('SATIN ALMA'!$F:$F, MATCH($F11, 'SATIN ALMA'!$R:$R, 0)),"Bulunamadı") -> Bulunamadı | C11: =IFERROR(INDEX('SATIN ALMA'!$C:$C, MATCH($F11, 'SATIN ALMA'!$R:$R, 0)),"Bulunamadı" ) -> Bulunamadı | D11: =IFERROR(INDEX('SATIN ALMA'!$D:$D, MATCH($F11, 'SATIN ALMA'!$R:$R, 0)),"Bulunamadı" ) -> Bulunamadı | E11: =IFERROR(INDEX('SATIN ALMA'!$O:$O, MATCH($F11, 'SATIN ALMA'!$R:$R, 0)),"Bulunamadı" ) -> Bulunamadı | G11: =IFERROR(INDEX('GİRİŞ ANALİZİ'!$D:$D, MATCH($F11, 'GİRİŞ ANALİZİ'!$C:$C, 0)),"Bulunamadı" ) -> Bulunamadı | H11: =IFERROR(INDEX('GİRİŞ ANALİZİ'!$E:$E, MATCH($F11, 'GİRİŞ ANALİZİ'!$C:$C, 0)),"Bulunamadı" ) -> Bulunamadı | I11: =IFERROR(INDEX('SATIN ALMA'!$S:$S, MATCH(F11, 'SATIN ALMA'!$R:$R, 0)),"Bulunamadı" ) -> Bulunamadı | J11: =IFERROR(INDEX('SATIN ALMA'!$T:$T, MATCH($F11, 'SATIN ALMA'!$R:$R, 0)),"Bulunamadı") -> Bulunamadı | K11: =IFERROR(INDEX('SATIN ALMA'!$V:$V, MATCH($F11, 'SATIN ALMA'!$R:$R, 0)),"Bulunamadı" ) -> Bulunamadı | L11: =IFERROR( INDEX('SATIN ALMA'!$W:$W, MATCH($F11, 'SATIN ALMA'!$R:$R, 0)), "Bulunamadı" ) -> Bulunamadı
A12: =IFERROR(HYPERLINK("#"&ADDRESS(MATCH($F12,'SATIN ALMA'!$R:$R,0),COLUMN('SATIN ALMA'!$R:$R),1,1,"SATIN ALMA"),"Git →"),"Bulunamadı") -> Bulunamadı | B12: =IFERROR(INDEX('SATIN ALMA'!$F:$F, MATCH($F12, 'SATIN ALMA'!$R:$R, 0)),"Bulunamadı") -> Bulunamadı | C12: =IFERROR(INDEX('SATIN ALMA'!$C:$C, MATCH($F12, 'SATIN ALMA'!$R:$R, 0)),"Bulunamadı" ) -> Bulunamadı | D12: =IFERROR(INDEX('SATIN ALMA'!$D:$D, MATCH($F12, 'SATIN ALMA'!$R:$R, 0)),"Bulunamadı" ) -> Bulunamadı | E12: =IFERROR(INDEX('SATIN ALMA'!$O:$O, MATCH($F12, 'SATIN ALMA'!$R:$R, 0)),"Bulunamadı" ) -> Bulunamadı | G12: =IFERROR(INDEX('GİRİŞ ANALİZİ'!$D:$D, MATCH($F12, 'GİRİŞ ANALİZİ'!$C:$C, 0)),"Bulunamadı" ) -> Bulunamadı | H12: =IFERROR(INDEX('GİRİŞ ANALİZİ'!$E:$E, MATCH($F12, 'GİRİŞ ANALİZİ'!$C:$C, 0)),"Bulunamadı" ) -> Bulunamadı | I12: =IFERROR(INDEX('SATIN ALMA'!$S:$S, MATCH(F12, 'SATIN ALMA'!$R:$R, 0)),"Bulunamadı" ) -> Bulunamadı | J12: =IFERROR(INDEX('SATIN ALMA'!$T:$T, MATCH($F12, 'SATIN ALMA'!$R:$R, 0)),"Bulunamadı") -> Bulunamadı | K12: =IFERROR(INDEX('SATIN ALMA'!$V:$V, MATCH($F12, 'SATIN ALMA'!$R:$R, 0)),"Bulunamadı" ) -> Bulunamadı | L12: =IFERROR( INDEX('SATIN ALMA'!$W:$W, MATCH($F12, 'SATIN ALMA'!$R:$R, 0)), "Bulunamadı" ) -> Bulunamadı
A13: =IFERROR(HYPERLINK("#"&ADDRESS(MATCH($F13,'SATIN ALMA'!$R:$R,0),COLUMN('SATIN ALMA'!$R:$R),1,1,"SATIN ALMA"),"Git →"),"Bulunamadı") -> Bulunamadı | B13: =IFERROR(INDEX('SATIN ALMA'!$F:$F, MATCH($F13, 'SATIN ALMA'!$R:$R, 0)),"Bulunamadı") -> Bulunamadı | C13: =IFERROR(INDEX('SATIN ALMA'!$C:$C, MATCH($F13, 'SATIN ALMA'!$R:$R, 0)),"Bulunamadı" ) -> Bulunamadı | D13: =IFERROR(INDEX('SATIN ALMA'!$D:$D, MATCH($F13, 'SATIN ALMA'!$R:$R, 0)),"Bulunamadı" ) -> Bulunamadı | E13: =IFERROR(INDEX('SATIN ALMA'!$O:$O, MATCH($F13, 'SATIN ALMA'!$R:$R, 0)),"Bulunamadı" ) -> Bulunamadı | G13: =IFERROR(INDEX('GİRİŞ ANALİZİ'!$D:$D, MATCH($F13, 'GİRİŞ ANALİZİ'!$C:$C, 0)),"Bulunamadı" ) -> Bulunamadı | H13: =IFERROR(INDEX('GİRİŞ ANALİZİ'!$E:$E, MATCH($F13, 'GİRİŞ ANALİZİ'!$C:$C, 0)),"Bulunamadı" ) -> Bulunamadı | I13: =IFERROR(INDEX('SATIN ALMA'!$S:$S, MATCH(F13, 'SATIN ALMA'!$R:$R, 0)),"Bulunamadı" ) -> Bulunamadı | J13: =IFERROR(INDEX('SATIN ALMA'!$T:$T, MATCH($F13, 'SATIN ALMA'!$R:$R, 0)),"Bulunamadı") -> Bulunamadı | K13: =IFERROR(INDEX('SATIN ALMA'!$V:$V, MATCH($F13, 'SATIN ALMA'!$R:$R, 0)),"Bulunamadı" ) -> Bulunamadı | L13: =IFERROR( INDEX('SATIN ALMA'!$W:$W, MATCH($F13, 'SATIN ALMA'!$R:$R, 0)), "Bulunamadı" ) -> Bulunamadı
A14: =IFERROR(HYPERLINK("#"&ADDRESS(MATCH($F14,'SATIN ALMA'!$R:$R,0),COLUMN('SATIN ALMA'!$R:$R),1,1,"SATIN ALMA"),"Git →"),"Bulunamadı") -> Bulunamadı | B14: =IFERROR(INDEX('SATIN ALMA'!$F:$F, MATCH($F14, 'SATIN ALMA'!$R:$R, 0)),"Bulunamadı") -> Bulunamadı | C14: =IFERROR(INDEX('SATIN ALMA'!$C:$C, MATCH($F14, 'SATIN ALMA'!$R:$R, 0)),"Bulunamadı" ) -> Bulunamadı | D14: =IFERROR(INDEX('SATIN ALMA'!$D:$D, MATCH($F14, 'SATIN ALMA'!$R:$R, 0)),"Bulunamadı" ) -> Bulunamadı | E14: =IFERROR(INDEX('SATIN ALMA'!$O:$O, MATCH($F14, 'SATIN ALMA'!$R:$R, 0)),"Bulunamadı" ) -> Bulunamadı | G14: =IFERROR(INDEX('GİRİŞ ANALİZİ'!$D:$D, MATCH($F14, 'GİRİŞ ANALİZİ'!$C:$C, 0)),"Bulunamadı" ) -> Bulunamadı | H14: =IFERROR(INDEX('GİRİŞ ANALİZİ'!$E:$E, MATCH($F14, 'GİRİŞ ANALİZİ'!$C:$C, 0)),"Bulunamadı" ) -> Bulunamadı | I14: =IFERROR(INDEX('SATIN ALMA'!$S:$S, MATCH(F14, 'SATIN ALMA'!$R:$R, 0)),"Bulunamadı" ) -> Bulunamadı | J14: =IFERROR(INDEX('SATIN ALMA'!$T:$T, MATCH($F14, 'SATIN ALMA'!$R:$R, 0)),"Bulunamadı") -> Bulunamadı | K14: =IFERROR(INDEX('SATIN ALMA'!$V:$V, MATCH($F14, 'SATIN ALMA'!$R:$R, 0)),"Bulunamadı" ) -> Bulunamadı | L14: =IFERROR( INDEX('SATIN ALMA'!$W:$W, MATCH($F14, 'SATIN ALMA'!$R:$R, 0)), "Bulunamadı" ) -> Bulunamadı
A15: =IFERROR(HYPERLINK("#"&ADDRESS(MATCH($F15,'SATIN ALMA'!$R:$R,0),COLUMN('SATIN ALMA'!$R:$R),1,1,"SATIN ALMA"),"Git →"),"Bulunamadı") -> Bulunamadı | B15: =IFERROR(INDEX('SATIN ALMA'!$F:$F, MATCH($F15, 'SATIN ALMA'!$R:$R, 0)),"Bulunamadı") -> Bulunamadı | C15: =IFERROR(INDEX('SATIN ALMA'!$C:$C, MATCH($F15, 'SATIN ALMA'!$R:$R, 0)),"Bulunamadı" ) -> Bulunamadı | D15: =IFERROR(INDEX('SATIN ALMA'!$D:$D, MATCH($F15, 'SATIN ALMA'!$R:$R, 0)),"Bulunamadı" ) -> Bulunamadı | E15: =IFERROR(INDEX('SATIN ALMA'!$O:$O, MATCH($F15, 'SATIN ALMA'!$R:$R, 0)),"Bulunamadı" ) -> Bulunamadı | G15: =IFERROR(INDEX('GİRİŞ ANALİZİ'!$D:$D, MATCH($F15, 'GİRİŞ ANALİZİ'!$C:$C, 0)),"Bulunamadı" ) -> Bulunamadı | H15: =IFERROR(INDEX('GİRİŞ ANALİZİ'!$E:$E, MATCH($F15, 'GİRİŞ ANALİZİ'!$C:$C, 0)),"Bulunamadı" ) -> Bulunamadı | I15: =IFERROR(INDEX('SATIN ALMA'!$S:$S, MATCH(F15, 'SATIN ALMA'!$R:$R, 0)),"Bulunamadı" ) -> Bulunamadı | J15: =IFERROR(INDEX('SATIN ALMA'!$T:$T, MATCH($F15, 'SATIN ALMA'!$R:$R, 0)),"Bulunamadı") -> Bulunamadı | K15: =IFERROR(INDEX('SATIN ALMA'!$V:$V, MATCH($F15, 'SATIN ALMA'!$R:$R, 0)),"Bulunamadı" ) -> Bulunamadı | L15: =IFERROR( INDEX('SATIN ALMA'!$W:$W, MATCH($F15, 'SATIN ALMA'!$R:$R, 0)), "Bulunamadı" ) -> Bulunamadı
J21: =IFERROR( INDEX('SATIN ALMA'!$T:$T, MATCH($F21, 'SATIN ALMA'!$R:$R, 0)), "" ) | K21: =IFERROR( INDEX('SATIN ALMA'!$V:$V, MATCH($F21, 'SATIN ALMA'!$R:$R, 0)), "" ) | L21: =IFERROR( INDEX('SATIN ALMA'!$W:$W, MATCH($F21, 'SATIN ALMA'!$R:$R, 0)), "" )
J22: =IFERROR( INDEX('SATIN ALMA'!$T:$T, MATCH($F22, 'SATIN ALMA'!$R:$R, 0)), "" ) | K22: =IFERROR( INDEX('SATIN ALMA'!$V:$V, MATCH($F22, 'SATIN ALMA'!$R:$R, 0)), "" ) | L22: =IFERROR( INDEX('SATIN ALMA'!$W:$W, MATCH($F22, 'SATIN ALMA'!$R:$R, 0)), "" )
J23: =IFERROR( INDEX('SATIN ALMA'!$T:$T, MATCH($F23, 'SATIN ALMA'!$R:$R, 0)), "" ) | K23: =IFERROR( INDEX('SATIN ALMA'!$V:$V, MATCH($F23, 'SATIN ALMA'!$R:$R, 0)), "" ) | L23: =IFERROR( INDEX('SATIN ALMA'!$W:$W, MATCH($F23, 'SATIN ALMA'!$R:$R, 0)), "" )
J24: =IFERROR( INDEX('SATIN ALMA'!$T:$T, MATCH($F24, 'SATIN ALMA'!$R:$R, 0)), "" ) | K24: =IFERROR( INDEX('SATIN ALMA'!$V:$V, MATCH($F24, 'SATIN ALMA'!$R:$R, 0)), "" ) | L24: =IFERROR( INDEX('SATIN ALMA'!$W:$W, MATCH($F24, 'SATIN ALMA'!$R:$R, 0)), "" )
J25: =IFERROR( INDEX('SATIN ALMA'!$T:$T, MATCH($F25, 'SATIN ALMA'!$R:$R, 0)), "" ) | K25: =IFERROR( INDEX('SATIN ALMA'!$V:$V, MATCH($F25, 'SATIN ALMA'!$R:$R, 0)), "" ) | L25: =IFERROR( INDEX('SATIN ALMA'!$W:$W, MATCH($F25, 'SATIN ALMA'!$R:$R, 0)), "" )
J26: =IFERROR( INDEX('SATIN ALMA'!$T:$T, MATCH($F26, 'SATIN ALMA'!$R:$R, 0)), "" ) | K26: =IFERROR( INDEX('SATIN ALMA'!$V:$V, MATCH($F26, 'SATIN ALMA'!$R:$R, 0)), "" ) | L26: =IFERROR( INDEX('SATIN ALMA'!$W:$W, MATCH($F26, 'SATIN ALMA'!$R:$R, 0)), "" )
J27: =IFERROR( INDEX('SATIN ALMA'!$T:$T, MATCH($F27, 'SATIN ALMA'!$R:$R, 0)), "" ) | K27: =IFERROR( INDEX('SATIN ALMA'!$V:$V, MATCH($F27, 'SATIN ALMA'!$R:$R, 0)), "" ) | L27: =IFERROR( INDEX('SATIN ALMA'!$W:$W, MATCH($F27, 'SATIN ALMA'!$R:$R, 0)), "" )

Sheet HENDEK-3
A1: Satın Alma Bağlantısı | B1: Firma Adı | C1: Contract No | D1: Stok Kodu | E1: Stok Adı | F1: Mahsul Yılı | G1: Kg | H1: Konteyner No | I1: Antrepo No | J1: Tır No | K1: B/L No | L1: Ref. No | M1: Parti No
A2: =IFERROR(HYPERLINK("#"&ADDRESS(MATCH($H2,'SATIN ALMA'!$R:$R,0),COLUMN('SATIN ALMA'!$R:$R),1,1,"SATIN ALMA"),"Git →"),"Bulunamadı") -> Git → | B2: =IFERROR(INDEX('SATIN ALMA'!$F:$F, MATCH($H2, 'SATIN ALMA'!$R:$R, 0)),"Bulunamadı") -> LIEN VIET | C2: =IFERROR(INDEX('SATIN ALMA'!$W:$W, MATCH($H2, 'SATIN ALMA'!$R:$R, 0)),"Bulunamadı") -> HD29412-2 | D2: =IFERROR(INDEX('SATIN ALMA'!$C:$C, MATCH($H2, 'SATIN ALMA'!$R:$R, 0)),"Bulunamadı") -> H5130003 | E2: =IFERROR(INDEX('SATIN ALMA'!$D:$D, MATCH($H2, 'SATIN ALMA'!$R:$R, 0)),"Bulunamadı") -> HW.CASHEW NUT W320____________( 22.68 KG ) | F2: 2024 | G2: 3606.12 | H2: =IFERROR(INDEX('SATIN ALMA'!$R:$R, MATCH($J2, 'SATIN ALMA'!$X:$X, 0)),"Bulunamadı" ) -> MSBU4022649 | J2: 30 | K2: =IFERROR(INDEX('SATIN ALMA'!$T:$T, MATCH($H2, 'SATIN ALMA'!$R:$R, 0)),"Bulunamadı") -> MEDUHQ575332 | L2: =IFERROR(INDEX('SATIN ALMA'!$V:$V, MATCH($H2, 'SATIN ALMA'!$R:$R, 0)),"Bulunamadı") -> 25261-IT25154191 | M2: 481735
A3: =IFERROR(HYPERLINK("#"&ADDRESS(MATCH($H3,'SATIN ALMA'!$R:$R,0),COLUMN('SATIN ALMA'!$R:$R),1,1,"SATIN ALMA"),"Git →"),"Bulunamadı") -> Git → | B3: =IFERROR(INDEX('SATIN ALMA'!$F:$F, MATCH($H3, 'SATIN ALMA'!$R:$R, 0)),"Bulunamadı") -> LIEN VIET | C3: =IFERROR(INDEX('SATIN ALMA'!$W:$W, MATCH($H3, 'SATIN ALMA'!$R:$R, 0)),"Bulunamadı") -> HD29412-5 | D3: =IFERROR(INDEX('SATIN ALMA'!$C:$C, MATCH($H3, 'SATIN ALMA'!$R:$R, 0)),"Bulunamadı") -> H5130003 | E3: =IFERROR(INDEX('SATIN ALMA'!$D:$D, MATCH($H3, 'SATIN ALMA'!$R:$R, 0)),"Bulunamadı") -> HW.CASHEW NUT W320____________( 22.68 KG ) | F3: 2024 | G3: 24267.6 | H3: =IFERROR(INDEX('SATIN ALMA'!$R:$R, MATCH($J3, 'SATIN ALMA'!$X:$X, 0)),"Bulunamadı" ) -> GAOU7622115 | J3: 31 | K3: =IFERROR(INDEX('SATIN ALMA'!$T:$T, MATCH($H3, 'SATIN ALMA'!$R:$R, 0)),"Bulunamadı") -> MEDUHQ721324 | L3: =IFERROR(INDEX('SATIN ALMA'!$V:$V, MATCH($H3, 'SATIN ALMA'!$R:$R, 0)),"Bulunamadı") -> 25261-IT25154191 | M3: 495565
A4: =IFERROR(HYPERLINK("#"&ADDRESS(MATCH($H4,'SATIN ALMA'!$R:$R,0),COLUMN('SATIN ALMA'!$R:$R),1,1,"SATIN ALMA"),"Git →"),"Bulunamadı") -> Git → | B4: =IFERROR(INDEX('SATIN ALMA'!$F:$F, MATCH($H4, 'SATIN ALMA'!$R:$R, 0)),"Bulunamadı") -> LIEN VIET | C4: =IFERROR(INDEX('SATIN ALMA'!$W:$W, MATCH($H4, 'SATIN ALMA'!$R:$R, 0)),"Bulunamadı") -> HD29412-4 | D4: =IFERROR(INDEX('SATIN ALMA'!$C:$C, MATCH($H4, 'SATIN ALMA'!$R:$R, 0)),"Bulunamadı") -> H5130003 | E4: =IFERROR(INDEX('SATIN ALMA'!$D:$D, MATCH($H4, 'SATIN ALMA'!$R:$R, 0)),"Bulunamadı") -> HW.CASHEW NUT W320____________( 22.68 KG ) | F4: 2025 | G4: 24267.6 | H4: =IFERROR(INDEX('SATIN ALMA'!$R:$R, MATCH($J4, 'SATIN ALMA'!$X:$X, 0)),"Bulunamadı" ) -> TXGU7262063 | I4: =IFERROR(INDEX('SATIN ALMA'!$S:$S, MATCH($J4, 'SATIN ALMA'!$X:$X, 0)),"Bulunamadı" ) -> AN00039126 | J4: 32 | K4: =IFERROR(INDEX('SATIN ALMA'!$T:$T, MATCH($H4, 'SATIN ALMA'!$R:$R, 0)),"Bulunamadı") -> MEDUHQ721324 | L4: =IFERROR(INDEX('SATIN ALMA'!$V:$V, MATCH($H4, 'SATIN ALMA'!$R:$R, 0)),"Bulunamadı") -> 25261-IT25154191 | M4: =IFERROR(INDEX('GİRİŞ ANALİZİ'!$E:$E, MATCH($H4, 'GİRİŞ ANALİZİ'!$C:$C, 0)),"Bulunamadı") -> 0
A5: =IFERROR(HYPERLINK("#"&ADDRESS(MATCH($H5,'SATIN ALMA'!$R:$R,0),COLUMN('SATIN ALMA'!$R:$R),1,1,"SATIN ALMA"),"Git →"),"Bulunamadı") -> Git → | B5: =IFERROR(INDEX('SATIN ALMA'!$F:$F, MATCH($H5, 'SATIN ALMA'!$R:$R, 0)),"Bulunamadı") -> LIEN VIET | C5: =IFERROR(INDEX('SATIN ALMA'!$W:$W, MATCH($H5, 'SATIN ALMA'!$R:$R, 0)),"Bulunamadı") -> HD29412-6 | D5: =IFERROR(INDEX('SATIN ALMA'!$C:$C, MATCH($H5, 'SATIN ALMA'!$R:$R, 0)),"Bulunamadı") -> H5130003 | E5: =IFERROR(INDEX('SATIN ALMA'!$D:$D, MATCH($H5, 'SATIN ALMA'!$R:$R, 0)),"Bulunamadı") -> HW.CASHEW NUT W320____________( 22.68 KG ) | F5: 2025 | G5: 7938 | H5: =IFERROR(INDEX('SATIN ALMA'!$R:$R, MATCH($J5, 'SATIN ALMA'!$X:$X, 0)),"Bulunamadı" ) -> MSDU7330895 | I5: =IFERROR(INDEX('SATIN ALMA'!$S:$S, MATCH($J5, 'SATIN ALMA'!$X:$X, 0)),"Bulunamadı" ) -> AN0003984 | J5: 34 | K5: =IFERROR(INDEX('SATIN ALMA'!$T:$T, MATCH($H5, 'SATIN ALMA'!$R:$R, 0)),"Bulunamadı") -> MEDUHQ769349 | L5: =IFERROR(INDEX('SATIN ALMA'!$V:$V, MATCH($H5, 'SATIN ALMA'!$R:$R, 0)),"Bulunamadı") -> 25261-IT25154191 | M5: =IFERROR(INDEX('GİRİŞ ANALİZİ'!$E:$E, MATCH($H5, 'GİRİŞ ANALİZİ'!$C:$C, 0)),"Bulunamadı") -> 508410
A6: =IFERROR(HYPERLINK("#"&ADDRESS(MATCH($H6,'SATIN ALMA'!$R:$R,0),COLUMN('SATIN ALMA'!$R:$R),1,1,"SATIN ALMA"),"Git →"),"Bulunamadı") -> Git → | B6: =IFERROR(INDEX('SATIN ALMA'!$F:$F, MATCH($H6, 'SATIN ALMA'!$R:$R, 0)),"Bulunamadı") -> NGAN NGOC | C6: =IFERROR(INDEX('SATIN ALMA'!$W:$W, MATCH($H6, 'SATIN ALMA'!$R:$R, 0)),"Bulunamadı") -> HD46212-1 | D6: =IFERROR(INDEX('SATIN ALMA'!$C:$C, MATCH($H6, 'SATIN ALMA'!$R:$R, 0)),"Bulunamadı") -> H5130003 | E6: =IFERROR(INDEX('SATIN ALMA'!$D:$D, MATCH($H6, 'SATIN ALMA'!$R:$R, 0)),"Bulunamadı") -> HW.CASHEW NUT W320____________( 22.68 KG ) | F6: 2024 | G6: 24267.6 | H6: =IFERROR(INDEX('SATIN ALMA'!$R:$R, MATCH($J6, 'SATIN ALMA'!$X:$X, 0)),"Bulunamadı" ) -> MSDU4075939 | J6: 35 | K6: =IFERROR(INDEX('SATIN ALMA'!$T:$T, MATCH($H6, 'SATIN ALMA'!$R:$R, 0)),"Bulunamadı") -> MEDUHQ833079 | L6: =IFERROR(INDEX('SATIN ALMA'!$V:$V, MATCH($H6, 'SATIN ALMA'!$R:$R, 0)),"Bulunamadı") -> 26001-IT26154001 | M6: 493152
